Workbook

Sheet Instructions
A1: H3 (Pan-Himalayan) Network Centrality Project — Data Collection Guide (v3)
A3: SHEET: Airport Parameters
A4: All 129 airports H3 holds gates at are pre-filled (IATA, name, lat, lon — real
A5: coordinates, already joined). You only need to fill in:
A6: H3 weekly pax — your own passengers per week at that destination.
A7: H3 market share % — read off that airport's competitor list in-game.
A8: Airport rank / Airport rank % — the in-game rank stat (secondary check only,
A9: used to test the Zipf/power-law hunch, NOT the primary size term).
A10: Total weekly pax fills in automatically once the two columns above are entered.
A12: SHEET: Calibration Routes
A13: 60 pairs are pre-selected for distance and size spread (using gate weekly cost as a
A14: size stand-in until real data exists) — only 1 pair touches KTM, deliberately, so
... A16: number from Route Research for each pair. Distance is already computed.

Sheet Airport Parameters
A1: IATA | B1: Airport name | C1: Lat | D1: Lon | E1: H3 weekly pax | F1: H3 market share % | G1: Total weekly pax (computed) | H1: Airport rank | I1: Airport rank % | J1: log(Rank) | K1: log(weeklyPax) | L1: Date collected | M1: Notes
A2: ABZ | B2: Aberdeen International Airport | C2: 57.2019 | D2: -2.1978 | E2: 704 | F2: 2.9 | G2: =ROUND(IF(F2=0,"",IF(F2="","",E2/(F2/100))),0) -> 24276 | H2: 607 | I2: 86.48 | J2: =LOG(H2) -> 2.7831887 | K2: =LOG(G2) -> 4.3851771
A3: AJL | B3: Lengpui Airport | C3: 23.8406 | D3: 92.6197 | E3: 1488 | F3: 100 | G3: =ROUND(IF(F3=0,"",IF(F3="","",E3/(F3/100))),0) -> 1488 | H3: 1388 | I3: 69.07 | J3: =LOG(H3) -> 3.1423895 | K3: =LOG(G3) -> 3.1726029
A4: AKU | B4: Akesu Hongqipo Airport | C4: 41.2625 | D4: 80.2917 | E4: 1084 | F4: 2.4 | G4: =ROUND(IF(F4=0,"",IF(F4="","",E4/(F4/100))),0) -> 45167 | H4: 546 | I4: 87.83 | J4: =LOG(H4) -> 2.7371926 | K4: =LOG(G4) -> 4.6548212
A5: AKY | B5: Sittwe Airport | C5: 20.1327 | D5: 92.8726 | E5: 513 | F5: 100 | G5: =ROUND(IF(F5=0,"",IF(F5="","",E5/(F5/100))),0) -> 513 | H5: 3211 | I5: 28.45 | J5: =LOG(H5) -> 3.5066403 | K5: =LOG(G5) -> 2.7101174
A6: ALA | B6: Almaty International Airport | C6: 43.3521 | D6: 77.0405 | E6: 1912 | F6: 1.2 | G6: =ROUND(IF(F6=0,"",IF(F6="","",E6/(F6/100))),0) -> 159333 | H6: 207 | I6: 95.39 | J6: =LOG(H6) -> 2.3159703 | K6: =LOG(G6) -> 5.2023057
A7: AMM | B7: Queen Alia International Airport | C7: 31.7226 | D7: 35.9932 | E7: 1224 | F7: 0.8 | G7: =ROUND(IF(F7=0,"",IF(F7="","",E7/(F7/100))),0) -> 153000 | H7: 275 | I7: 93.87 | J7: =LOG(H7) -> 2.4393327 | K7: =LOG(G7) -> 5.1846914
A8: ATL | B8: Hartsfield-Jackson Atlanta International Airport | C8: 33.6367 | D8: -84.4281 | E8: 1475 | F8: 0.1 | G8: =ROUND(IF(F8=0,"",IF(F8="","",E8/(F8/100))),0) -> 1475000 | H8: 1 | I8: 99.98 | J8: =LOG(H8) -> 0 | K8: =LOG(G8) -> 6.168792
A9: BBI | B9: Biju Patnaik Airport | C9: 20.2444 | D9: 85.8178 | E9: 762 | F9: 0.7 | G9: =ROUND(IF(F9=0,"",IF(F9="","",E9/(F9/100))),0) -> 108857 | H9: 384 | I9: 91.44 | J9: =LOG(H9) -> 2.5843312 | K9: =LOG(G9) -> 5.0368564
A10: BEY | B10: Beirut–Rafic Hariri International Airport | C10: 33.8209 | D10: 35.4884 | E10: 762 | F10: 0.3 | G10: =ROUND(IF(F10=0,"",IF(F10="","",E10/(F10/100))),0) -> 254000 | H10: 293 | I10: 93.47 | J10: =LOG(H10) -> 2.4668676 | K10: =LOG(G10) -> 5.4048337
A11: BGW | B11: Baghdad International Airport | C11: 33.2625 | D11: 44.2346 | E11: 0 | F11: 0 | G11: 83789 | H11: 528 | I11: 88.24 | J11: =LOG(H11) -> 2.7226339 | K11: =LOG(G11) -> 4.923187
A12: BHK | B12: Bukhara International Airport | C12: 39.775 | D12: 64.4833 | E12: 562 | F12: 2.7 | G12: =ROUND(IF(F12=0,"",IF(F12="","",E12/(F12/100))),0) -> 20815 | H12: 1245 | I12: 72.26 | J12: =LOG(H12) -> 3.0951694 | K12: =LOG(G12) -> 4.3183764
A13: BKK | B13: Suvarnabhumi Airport | C13: 13.6811 | D13: 100.747 | E13: 2460 | F13: 0.8 | G13: =ROUND(IF(F13=0,"",IF(F13="","",E13/(F13/100))),0) -> 307500 | H13: 22 | I13: 99.51 | J13: =LOG(H13) -> 1.3424227 | K13: =LOG(G13) -> 5.4878451
A14: BLR | B14: Kempegowda International Airport | C14: 13.1979 | D14: 77.7063 | E14: 1768 | F14: 0.1 | G14: =ROUND(IF(F14=0,"",IF(F14="","",E14/(F14/100))),0) -> 1768000 | H14: 58 | I14: 98.71 | J14: =LOG(H14) -> 1.763428 | K14: =LOG(G14) -> 6.2474823
A15: BOM | B15: Chhatrapati Shivaji Maharaj International Airport | C15: 19.0887 | D15: 72.8679 | E15: 1768 | F15: 0.1 | G15: =ROUND(IF(F15=0,"",IF(F15="","",E15/(F15/100))),0) -> 1768000 | H15: 29 | I15: 99.35 | J15: =LOG(H15) -> 1.462398 | K15: =LOG(G15) -> 6.2474823
A16: BPX | B16: Changdu Bamda Airport | C16: 30.5536 | D16: 97.1083 | E16: 768 | F16: 27.7 | G16: =ROUND(IF(F16=0,"",IF(F16="","",E16/(F16/100))),0) -> 2773 | H16: 1296 | I16: 71.18 | J16: =LOG(H16) -> 3.112605 | K16: =LOG(G16) -> 3.4429499
A17: BSZ | B17: Manas International Airport | C17: 43.0613 | D17: 74.4776 | E17: 1912 | F17: 3.3 | G17: =ROUND(IF(F17=0,"",IF(F17="","",E17/(F17/100))),0) -> 57939 | H17: 452 | I17: 89.93 | J17: =LOG(H17) -> 2.6551384 | K17: =LOG(G17) -> 4.762971
A18: BWA | B18: Gautam Buddha Airport | C18: 27.5057 | D18: 83.4163 | E18: 775 | F18: 17.4 | G18: =ROUND(IF(F18=0,"",IF(F18="","",E18/(F18/100))),0) -> 4454 | H18: 1642 | I18: 63.41 | J18: =LOG(H18) -> 3.2153732 | K18: =LOG(G18) -> 3.6487502
A19: CAN | B19: Guangzhou Baiyun International Airport | C19: 23.3924 | D19: 113.299 | E19: 1072 | F19: 0.1 | G19: =ROUND(IF(F19=0,"",IF(F19="","",E19/(F19/100))),0) -> 1072000 | H19: 9 | I19: 99.8 | J19: =LOG(H19) -> 0.95424251 | K19: =LOG(G19) -> 6.0301948
A20: CCU | B20: Netaji Subhas Chandra Bose International Airport | C20: 22.6547 | D20: 88.4467 | E20: 2056 | F20: 0.2 | G20: =ROUND(IF(F20=0,"",IF(F20="","",E20/(F20/100))),0) -> 1028000 | H20: 136 | I20: 96.97 | J20: =LOG(H20) -> 2.1335389 | K20: =LOG(G20) -> 6.0119931
A21: CEI | B21: Mae Fah Luang - Chiang Rai International Airport | C21: 19.9523 | D21: 99.8829 | E21: 804 | F21: 2.2 | G21: =ROUND(IF(F21=0,"",IF(F21="","",E21/(F21/100))),0) -> 36545 | H21: 667 | I21: 85.14 | J21: =LOG(H21) -> 2.8241258 | K21: =LOG(G21) -> 4.562828
A22: CGK | B22: Soekarno–Hatta International Airport | C22: -6.1256 | D22: 106.656 | E22: 2046 | F22: 0.4 | G22: =ROUND(IF(F22=0,"",IF(F22="","",E22/(F22/100))),0) -> 511500 | H22: 28 | I22: 99.38 | J22: =LOG(H22) -> 1.447158 | K22: =LOG(G22) -> 5.7088456
A23: CGP | B23: Shah Amanat International Airport | C23: 22.2496 | D23: 91.8133 | E23: 828 | F23: 2.7 | G23: =ROUND(IF(F23=0,"",IF(F23="","",E23/(F23/100))),0) -> 30667 | H23: 719 | I23: 83.98 | J23: =LOG(H23) -> 2.8567289 | K23: =LOG(G23) -> 4.4866713
... A29: DAC | B29: Hazrat Shahjalal International Airport | C29: 23.8433 | D29: 90.3978 | E29: 1488 | F29: 0.7 | G29: =ROUND(IF(F29=0,"",IF(F29="","",E29/(F29/100))),0) -> 212571 | H29: 191 | I29: 95.74 | J29: =LOG(H29) -> 2.2810334 | K29: =LOG(G29) -> 5.327504
A30: DAM | B30: Damascus International Airport | C30: 33.4115 | D30: 36.5156 | E30: 0 | F30: 0 | G30: 40437 | H30: 476 | I30: 89.39 | J30: =LOG(H30) -> 2.677607 | K30: =LOG(G30) -> 4.6067789
A31: DCY | B31: Daocheng Yading Airport | C31: 29.3231 | D31: 100.0533 | E31: 1005 | F31: 21.9 | G31: =ROUND(IF(F31=0,"",IF(F31="","",E31/(F31/100))),0) -> 4589 | H31: 2136 | I31: 52.41 | J31: =LOG(H31) -> 3.3296012 | K31: =LOG(G31) -> 3.6617181
A32: DED | B32: Dehradun Airport | C32: 30.1897 | D32: 78.1803 | E32: 1528 | F32: 2.1 | G32: =ROUND(IF(F32=0,"",IF(F32="","",E32/(F32/100))),0) -> 72762 | H32: 733 | I32: 83.67 | J32: =LOG(H32) -> 2.865104 | K32: =LOG(G32) -> 4.8619046
A33: DEL | B33: Indira Gandhi International Airport | C33: 28.5665 | D33: 77.1031 | E33: 3574 | F33: 0.2 | G33: =ROUND(IF(F33=0,"",IF(F33="","",E33/(F33/100))),0) -> 1787000 | H33: 11 | I33: 99.75 | J33: =LOG(H33) -> 1.0413927 | K33: =LOG(G33) -> 6.2521246
A34: DIB | B34: Dibrugarh Airport | C34: 27.4839 | D34: 95.0169 | E34: 2016 | F34: 100 | G34: =ROUND(IF(F34=0,"",IF(F34="","",E34/(F34/100))),0) -> 2016 | H34: 1088 | I34: 75.8 | J34: =LOG(H34) -> 3.0366289 | K34: =LOG(G34) -> 3.3044905
A35: DIG | B35: Diqing Shangri-La Airport | C35: 27.7936 | D35: 99.6772 | E35: 1048 | F35: 15.6 | G35: =ROUND(IF(F35=0,"",IF(F35="","",E35/(F35/100))),0) -> 6718 | H35: 1348 | I35: 69.96 | J35: =LOG(H35) -> 3.1296899 | K35: =LOG(G35) -> 3.82724
A36: DLU | B36: Dali Fengyi Airport | C36: 25.6494 | D36: 100.319 | E36: 730 | F36: 2.8 | G36: =ROUND(IF(F36=0,"",IF(F36="","",E36/(F36/100))),0) -> 26071 | H36: 436 | I36: 90.29 | J36: =LOG(H36) -> 2.6394865 | K36: =LOG(G36) -> 4.4161577
A37: DMU | B37: Dimapur Airport | C37: 25.8839 | D37: 93.7711 | E37: 1048 | F37: 100 | G37: =ROUND(IF(F37=0,"",IF(F37="","",E37/(F37/100))),0) -> 1048 | H37: 1506 | I37: 66.44 | J37: =LOG(H37) -> 3.177825 | K37: =LOG(G37) -> 3.0203613
A38: DOH | B38: Hamad International Airport | C38: 25.2731 | D38: 51.6081 | E38: 2046 | F38: 0.4 | G38: =ROUND(IF(F38=0,"",IF(F38="","",E38/(F38/100))),0) -> 511500 | H38: 32 | I38: 99.29 | J38: =LOG(H38) -> 1.50515 | K38: =LOG(G38) -> 5.7088456
A39: DXB | B39: Dubai International Airport | C39: 25.2528 | D39: 55.3644 | E39: 2055 | F39: 0.3 | G39: =ROUND(IF(F39=0,"",IF(F39="","",E39/(F39/100))),0) -> 685000 | H39: 2 | I39: 99.96 | J39: =LOG(H39) -> 0.30103 | K39: =LOG(G39) -> 5.8356906
A40: DYU | B40: Dushanbe International Airport | C40: 38.5433 | D40: 68.825 | E40: 1376 | F40: 4.1 | G40: =ROUND(IF(F40=0,"",IF(F40="","",E40/(F40/100))),0) -> 33561 | H40: 596 | I40: 86.72 | J40: =LOG(H40) -> 2.7752463 | K40: =LOG(G40) -> 4.5258349
A41: EDI | B41: Edinburgh Airport | C41: 55.95 | D41: -3.3725 | E41: 1480 | F41: 0.5 | G41: =ROUND(IF(F41=0,"",IF(F41="","",E41/(F41/100))),0) -> 296000 | H41: 159 | I41: 96.46 | J41: =LOG(H41) -> 2.2013971 | K41: =LOG(G41) -> 5.4712917
A42: ELP | B42: El Paso International Airport | C42: 31.8072 | D42: -106.378 | E42: 0 | F42: 0 | G42: 239170 | H42: 432 | I42: 90.37 | J42: =LOG(H42) -> 2.6354837 | K42: =LOG(G42) -> 5.3787067
A43: ESB | B43: Ankara Esenboğa Airport | C43: 40.1281 | D43: 32.9951 | E43: 1070 | F43: 0.3 | G43: =ROUND(IF(F43=0,"",IF(F43="","",E43/(F43/100))),0) -> 356667 | H43: 187 | I43: 95.83 | J43: =LOG(H43) -> 2.2718416 | K43: =LOG(G43) -> 5.5522629
A44: FAE | B44: Vágar Airport | C44: 62.0636 | D44: -7.2772 | E44: 668 | F44: 1.1 | G44: =ROUND(IF(F44=0,"",IF(F44="","",E44/(F44/100))),0) -> 60727 | H44: 1414 | I44: 68.49 | J44: =LOG(H44) -> 3.1504494 | K44: =LOG(G44) -> 4.7833818
A45: FNJ | B45: Pyongyang International Airport | C45: 39.2241 | D45: 125.67 | E45: 797 | F45: 8.2 | G45: =ROUND(IF(F45=0,"",IF(F45="","",E45/(F45/100))),0) -> 9720 | H45: 2441 | I45: 45.61 | J45: =LOG(H45) -> 3.3875678 | K45: =LOG(G45) -> 3.9876663
...

Sheet Calibration Routes
A1: Origin IATA | B1: Destination IATA | C1: Max Pax per Flight | D1: Distance nm (computed) | E1: Origin Size | F1: Destination Size | G1: Date collected | H1: Notes
A2: JRH | B2: SHL | C2: 210 | D2: =IFERROR(2*3440.065*ASIN(SQRT(SIN(RADIANS(VLOOKUP($B2,'Airport Parameters'!$A:$D,3,FALSE())-VLOOKUP($A2,'Airport Parameters'!$A:$D,3,FALSE()))/2)^2+COS(RADIANS(VLOOKUP($A2,'Airport Parameters'!$A:$D,3,FALSE())))*COS(RADIANS(VLOOKUP($B2,'Airport Parameters'!$A:$D,3,FALSE())))*SIN(RADIANS(VLOOKUP($B2,'Airport Parameters'!$A:$D,4,FALSE())-VLOOKUP($A2,'Airport Parameters'!$A:$D,4,FALSE()))/2)^2)),"") -> 133.45143 | E2: =VLOOKUP(A2,'Airport Parameters'!$A:$G,7,FALSE) -> 1048 | F2: =VLOOKUP(B2,'Airport Parameters'!$A:$G,7,FALSE) -> 704
A3: AKY | B3: MDL | C3: 119 | D3: =IFERROR(2*3440.065*ASIN(SQRT(SIN(RADIANS(VLOOKUP($B3,'Airport Parameters'!$A:$D,3,FALSE())-VLOOKUP($A3,'Airport Parameters'!$A:$D,3,FALSE()))/2)^2+COS(RADIANS(VLOOKUP($A3,'Airport Parameters'!$A:$D,3,FALSE())))*COS(RADIANS(VLOOKUP($B3,'Airport Parameters'!$A:$D,3,FALSE())))*SIN(RADIANS(VLOOKUP($B3,'Airport Parameters'!$A:$D,4,FALSE())-VLOOKUP($A3,'Airport Parameters'!$A:$D,4,FALSE()))/2)^2)),"") -> 198.00674 | E3: =VLOOKUP(A3,'Airport Parameters'!$A:$G,7,FALSE) -> 513 | F3: =VLOOKUP(B3,'Airport Parameters'!$A:$G,7,FALSE) -> 16511
A4: HTN | B4: IXL | C4: 386 | D4: =IFERROR(2*3440.065*ASIN(SQRT(SIN(RADIANS(VLOOKUP($B4,'Airport Parameters'!$A:$D,3,FALSE())-VLOOKUP($A4,'Airport Parameters'!$A:$D,3,FALSE()))/2)^2+COS(RADIANS(VLOOKUP($A4,'Airport Parameters'!$A:$D,3,FALSE())))*COS(RADIANS(VLOOKUP($B4,'Airport Parameters'!$A:$D,3,FALSE())))*SIN(RADIANS(VLOOKUP($B4,'Airport Parameters'!$A:$D,4,FALSE())-VLOOKUP($A4,'Airport Parameters'!$A:$D,4,FALSE()))/2)^2)),"") -> 207.79296 | E4: =VLOOKUP(A4,'Airport Parameters'!$A:$G,7,FALSE) -> 74444 | F4: =VLOOKUP(B4,'Airport Parameters'!$A:$G,7,FALSE) -> 77857
A5: AMM | B5: NUM | C5: 168 | D5: =IFERROR(2*3440.065*ASIN(SQRT(SIN(RADIANS(VLOOKUP($B5,'Airport Parameters'!$A:$D,3,FALSE())-VLOOKUP($A5,'Airport Parameters'!$A:$D,3,FALSE()))/2)^2+COS(RADIANS(VLOOKUP($A5,'Airport Parameters'!$A:$D,3,FALSE())))*COS(RADIANS(VLOOKUP($B5,'Airport Parameters'!$A:$D,3,FALSE())))*SIN(RADIANS(VLOOKUP($B5,'Airport Parameters'!$A:$D,4,FALSE())-VLOOKUP($A5,'Airport Parameters'!$A:$D,4,FALSE()))/2)^2)),"") -> 228.68662 | E5: =VLOOKUP(A5,'Airport Parameters'!$A:$G,7,FALSE) -> 153000 | F5: =VLOOKUP(B5,'Airport Parameters'!$A:$G,7,FALSE) -> 340
A6: CXB | B6: SHL | C6: 167 | D6: =IFERROR(2*3440.065*ASIN(SQRT(SIN(RADIANS(VLOOKUP($B6,'Airport Parameters'!$A:$D,3,FALSE())-VLOOKUP($A6,'Airport Parameters'!$A:$D,3,FALSE()))/2)^2+COS(RADIANS(VLOOKUP($A6,'Airport Parameters'!$A:$D,3,FALSE())))*COS(RADIANS(VLOOKUP($B6,'Airport Parameters'!$A:$D,3,FALSE())))*SIN(RADIANS(VLOOKUP($B6,'Airport Parameters'!$A:$D,4,FALSE())-VLOOKUP($A6,'Airport Parameters'!$A:$D,4,FALSE()))/2)^2)),"") -> 255.25731 | E6: =VLOOKUP(A6,'Airport Parameters'!$A:$G,7,FALSE) -> 2216 | F6: =VLOOKUP(B6,'Airport Parameters'!$A:$G,7,FALSE) -> 704
A7: KBL | B7: LHE | C7: 420 | D7: =IFERROR(2*3440.065*ASIN(SQRT(SIN(RADIANS(VLOOKUP($B7,'Airport Parameters'!$A:$D,3,FALSE())-VLOOKUP($A7,'Airport Parameters'!$A:$D,3,FALSE()))/2)^2+COS(RADIANS(VLOOKUP($A7,'Airport Parameters'!$A:$D,3,FALSE())))*COS(RADIANS(VLOOKUP($B7,'Airport Parameters'!$A:$D,3,FALSE())))*SIN(RADIANS(VLOOKUP($B7,'Airport Parameters'!$A:$D,4,FALSE())-VLOOKUP($A7,'Airport Parameters'!$A:$D,4,FALSE()))/2)^2)),"") -> 318.78308 | E7: =VLOOKUP(A7,'Airport Parameters'!$A:$G,7,FALSE) -> 159333 | F7: =VLOOKUP(B7,'Airport Parameters'!$A:$G,7,FALSE) -> 173818
A8: AKY | B8: MYT | C8: 105 | D8: =IFERROR(2*3440.065*ASIN(SQRT(SIN(RADIANS(VLOOKUP($B8,'Airport Parameters'!$A:$D,3,FALSE())-VLOOKUP($A8,'Airport Parameters'!$A:$D,3,FALSE()))/2)^2+COS(RADIANS(VLOOKUP($A8,'Airport Parameters'!$A:$D,3,FALSE())))*COS(RADIANS(VLOOKUP($B8,'Airport Parameters'!$A:$D,3,FALSE())))*SIN(RADIANS(VLOOKUP($B8,'Airport Parameters'!$A:$D,4,FALSE())-VLOOKUP($A8,'Airport Parameters'!$A:$D,4,FALSE()))/2)^2)),"") -> 401.03248 | E8: =VLOOKUP(A8,'Airport Parameters'!$A:$G,7,FALSE) -> 513 | F8: =VLOOKUP(B8,'Airport Parameters'!$A:$G,7,FALSE) -> 508
A9: LPQ | B9: SAI | C9: 419 | D9: =IFERROR(2*3440.065*ASIN(SQRT(SIN(RADIANS(VLOOKUP($B9,'Airport Parameters'!$A:$D,3,FALSE())-VLOOKUP($A9,'Airport Parameters'!$A:$D,3,FALSE()))/2)^2+COS(RADIANS(VLOOKUP($A9,'Airport Parameters'!$A:$D,3,FALSE())))*COS(RADIANS(VLOOKUP($B9,'Airport Parameters'!$A:$D,3,FALSE())))*SIN(RADIANS(VLOOKUP($B9,'Airport Parameters'!$A:$D,4,FALSE())-VLOOKUP($A9,'Airport Parameters'!$A:$D,4,FALSE()))/2)^2)),"") -> 409.09603 | E9: =VLOOKUP(A9,'Airport Parameters'!$A:$G,7,FALSE) -> 14941 | F9: =VLOOKUP(B9,'Airport Parameters'!$A:$G,7,FALSE) -> 51000
A10: DLU | B10: VTE | C10: 518 | D10: =IFERROR(2*3440.065*ASIN(SQRT(SIN(RADIANS(VLOOKUP($B10,'Airport Parameters'!$A:$D,3,FALSE())-VLOOKUP($A10,'Airport Parameters'!$A:$D,3,FALSE()))/2)^2+COS(RADIANS(VLOOKUP($A10,'Airport Parameters'!$A:$D,3,FALSE())))*COS(RADIANS(VLOOKUP($B10,'Airport Parameters'!$A:$D,3,FALSE())))*SIN(RADIANS(VLOOKUP($B10,'Airport Parameters'!$A:$D,4,FALSE())-VLOOKUP($A10,'Airport Parameters'!$A:$D,4,FALSE()))/2)^2)),"") -> 476.64229 | E10: =VLOOKUP(A10,'Airport Parameters'!$A:$G,7,FALSE) -> 26071 | F10: =VLOOKUP(B10,'Airport Parameters'!$A:$G,7,FALSE) -> 44905
A11: DCY | B11: GOQ | C11: 238 | D11: =IFERROR(2*3440.065*ASIN(SQRT(SIN(RADIANS(VLOOKUP($B11,'Airport Parameters'!$A:$D,3,FALSE())-VLOOKUP($A11,'Airport Parameters'!$A:$D,3,FALSE()))/2)^2+COS(RADIANS(VLOOKUP($A11,'Airport Parameters'!$A:$D,3,FALSE())))*COS(RADIANS(VLOOKUP($B11,'Airport Parameters'!$A:$D,3,FALSE())))*SIN(RADIANS(VLOOKUP($B11,'Airport Parameters'!$A:$D,4,FALSE())-VLOOKUP($A11,'Airport Parameters'!$A:$D,4,FALSE()))/2)^2)),"") -> 500.91779 | E11: =VLOOKUP(A11,'Airport Parameters'!$A:$G,7,FALSE) -> 4589 | F11: =VLOOKUP(B11,'Airport Parameters'!$A:$G,7,FALSE) -> 604
A12: MDL | B12: RKZ | C12: 286 | D12: =IFERROR(2*3440.065*ASIN(SQRT(SIN(RADIANS(VLOOKUP($B12,'Airport Parameters'!$A:$D,3,FALSE())-VLOOKUP($A12,'Airport Parameters'!$A:$D,3,FALSE()))/2)^2+COS(RADIANS(VLOOKUP($A12,'Airport Parameters'!$A:$D,3,FALSE())))*COS(RADIANS(VLOOKUP($B12,'Airport Parameters'!$A:$D,3,FALSE())))*SIN(RADIANS(VLOOKUP($B12,'Airport Parameters'!$A:$D,4,FALSE())-VLOOKUP($A12,'Airport Parameters'!$A:$D,4,FALSE()))/2)^2)),"") -> 583.99553 | E12: =VLOOKUP(A12,'Airport Parameters'!$A:$G,7,FALSE) -> 16511 | F12: =VLOOKUP(B12,'Airport Parameters'!$A:$G,7,FALSE) -> 450
A13: HAN | B13: JRH | C13: 339 | D13: =IFERROR(2*3440.065*ASIN(SQRT(SIN(RADIANS(VLOOKUP($B13,'Airport Parameters'!$A:$D,3,FALSE())-VLOOKUP($A13,'Airport Parameters'!$A:$D,3,FALSE()))/2)^2+COS(RADIANS(VLOOKUP($A13,'Airport Parameters'!$A:$D,3,FALSE())))*COS(RADIANS(VLOOKUP($B13,'Airport Parameters'!$A:$D,3,FALSE())))*SIN(RADIANS(VLOOKUP($B13,'Airport Parameters'!$A:$D,4,FALSE())-VLOOKUP($A13,'Airport Parameters'!$A:$D,4,FALSE()))/2)^2)),"") -> 718.25953 | E13: =VLOOKUP(A13,'Airport Parameters'!$A:$G,7,FALSE) -> 315667 | F13: =VLOOKUP(B13,'Airport Parameters'!$A:$G,7,FALSE) -> 1048
... A28: CTU | B28: KHG | C28: 623 | D28: =IFERROR(2*3440.065*ASIN(SQRT(SIN(RADIANS(VLOOKUP($B28,'Airport Parameters'!$A:$D,3,FALSE())-VLOOKUP($A28,'Airport Parameters'!$A:$D,3,FALSE()))/2)^2+COS(RADIANS(VLOOKUP($A28,'Airport Parameters'!$A:$D,3,FALSE())))*COS(RADIANS(VLOOKUP($B28,'Airport Parameters'!$A:$D,3,FALSE())))*SIN(RADIANS(VLOOKUP($B28,'Airport Parameters'!$A:$D,4,FALSE())-VLOOKUP($A28,'Airport Parameters'!$A:$D,4,FALSE()))/2)^2)),"") -> 1466.7647 | E28: =VLOOKUP(A28,'Airport Parameters'!$A:$G,7,FALSE) -> 536000 | F28: =VLOOKUP(B28,'Airport Parameters'!$A:$G,7,FALSE) -> 127467
A29: CGK | B29: MNL | C29: 401 | D29: =IFERROR(2*3440.065*ASIN(SQRT(SIN(RADIANS(VLOOKUP($B29,'Airport Parameters'!$A:$D,3,FALSE())-VLOOKUP($A29,'Airport Parameters'!$A:$D,3,FALSE()))/2)^2+COS(RADIANS(VLOOKUP($A29,'Airport Parameters'!$A:$D,3,FALSE())))*COS(RADIANS(VLOOKUP($B29,'Airport Parameters'!$A:$D,3,FALSE())))*SIN(RADIANS(VLOOKUP($B29,'Airport Parameters'!$A:$D,4,FALSE())-VLOOKUP($A29,'Airport Parameters'!$A:$D,4,FALSE()))/2)^2)),"") -> 1505.4782 | E29: =VLOOKUP(A29,'Airport Parameters'!$A:$G,7,FALSE) -> 511500 | F29: =VLOOKUP(B29,'Airport Parameters'!$A:$G,7,FALSE) -> 889000 | H29: Moderate competition for Y, Y+, low overall demanc
A30: BSZ | B30: MYT | C30: 314 | D30: =IFERROR(2*3440.065*ASIN(SQRT(SIN(RADIANS(VLOOKUP($B30,'Airport Parameters'!$A:$D,3,FALSE())-VLOOKUP($A30,'Airport Parameters'!$A:$D,3,FALSE()))/2)^2+COS(RADIANS(VLOOKUP($A30,'Airport Parameters'!$A:$D,3,FALSE())))*COS(RADIANS(VLOOKUP($B30,'Airport Parameters'!$A:$D,3,FALSE())))*SIN(RADIANS(VLOOKUP($B30,'Airport Parameters'!$A:$D,4,FALSE())-VLOOKUP($A30,'Airport Parameters'!$A:$D,4,FALSE()))/2)^2)),"") -> 1544.6785 | E30: =VLOOKUP(A30,'Airport Parameters'!$A:$G,7,FALSE) -> 57939 | F30: =VLOOKUP(B30,'Airport Parameters'!$A:$G,7,FALSE) -> 508
A31: ICN | B31: LZY | C31: 509 | D31: =IFERROR(2*3440.065*ASIN(SQRT(SIN(RADIANS(VLOOKUP($B31,'Airport Parameters'!$A:$D,3,FALSE())-VLOOKUP($A31,'Airport Parameters'!$A:$D,3,FALSE()))/2)^2+COS(RADIANS(VLOOKUP($A31,'Airport Parameters'!$A:$D,3,FALSE())))*COS(RADIANS(VLOOKUP($B31,'Airport Parameters'!$A:$D,3,FALSE())))*SIN(RADIANS(VLOOKUP($B31,'Airport Parameters'!$A:$D,4,FALSE())-VLOOKUP($A31,'Airport Parameters'!$A:$D,4,FALSE()))/2)^2)),"") -> 1673.7732 | E31: =VLOOKUP(A31,'Airport Parameters'!$A:$G,7,FALSE) -> 637333 | F31: =VLOOKUP(B31,'Airport Parameters'!$A:$G,7,FALSE) -> 19429
A32: DIG | B32: SKD | C32: 277 | D32: =IFERROR(2*3440.065*ASIN(SQRT(SIN(RADIANS(VLOOKUP($B32,'Airport Parameters'!$A:$D,3,FALSE())-VLOOKUP($A32,'Airport Parameters'!$A:$D,3,FALSE()))/2)^2+COS(RADIANS(VLOOKUP($A32,'Airport Parameters'!$A:$D,3,FALSE())))*COS(RADIANS(VLOOKUP($B32,'Airport Parameters'!$A:$D,3,FALSE())))*SIN(RADIANS(VLOOKUP($B32,'Airport Parameters'!$A:$D,4,FALSE())-VLOOKUP($A32,'Airport Parameters'!$A:$D,4,FALSE()))/2)^2)),"") -> 1769.1102 | E32: =VLOOKUP(A32,'Airport Parameters'!$A:$G,7,FALSE) -> 6718 | F32: =VLOOKUP(B32,'Airport Parameters'!$A:$G,7,FALSE) -> 18169
A33: ALA | B33: RUH | C33: 657 | D33: =IFERROR(2*3440.065*ASIN(SQRT(SIN(RADIANS(VLOOKUP($B33,'Airport Parameters'!$A:$D,3,FALSE())-VLOOKUP($A33,'Airport Parameters'!$A:$D,3,FALSE()))/2)^2+COS(RADIANS(VLOOKUP($A33,'Airport Parameters'!$A:$D,3,FALSE())))*COS(RADIANS(VLOOKUP($B33,'Airport Parameters'!$A:$D,3,FALSE())))*SIN(RADIANS(VLOOKUP($B33,'Airport Parameters'!$A:$D,4,FALSE())-VLOOKUP($A33,'Airport Parameters'!$A:$D,4,FALSE()))/2)^2)),"") -> 1851.6097 | E33: =VLOOKUP(A33,'Airport Parameters'!$A:$G,7,FALSE) -> 159333 | F33: =VLOOKUP(B33,'Airport Parameters'!$A:$G,7,FALSE) -> 356667
A34: GZG | B34: TRV | C34: 262 | D34: =IFERROR(2*3440.065*ASIN(SQRT(SIN(RADIANS(VLOOKUP($B34,'Airport Parameters'!$A:$D,3,FALSE())-VLOOKUP($A34,'Airport Parameters'!$A:$D,3,FALSE()))/2)^2+COS(RADIANS(VLOOKUP($A34,'Airport Parameters'!$A:$D,3,FALSE())))*COS(RADIANS(VLOOKUP($B34,'Airport Parameters'!$A:$D,3,FALSE())))*SIN(RADIANS(VLOOKUP($B34,'Airport Parameters'!$A:$D,4,FALSE())-VLOOKUP($A34,'Airport Parameters'!$A:$D,4,FALSE()))/2)^2)),"") -> 1888.9911 | E34: =VLOOKUP(A34,'Airport Parameters'!$A:$G,7,FALSE) -> 3014 | F34: =VLOOKUP(B34,'Airport Parameters'!$A:$G,7,FALSE) -> 471500
A35: CGK | B35: IXI | C35: 250 | D35: =IFERROR(2*3440.065*ASIN(SQRT(SIN(RADIANS(VLOOKUP($B35,'Airport Parameters'!$A:$D,3,FALSE())-VLOOKUP($A35,'Airport Parameters'!$A:$D,3,FALSE()))/2)^2+COS(RADIANS(VLOOKUP($A35,'Airport Parameters'!$A:$D,3,FALSE())))*COS(RADIANS(VLOOKUP($B35,'Airport Parameters'!$A:$D,3,FALSE())))*SIN(RADIANS(VLOOKUP($B35,'Airport Parameters'!$A:$D,4,FALSE())-VLOOKUP($A35,'Airport Parameters'!$A:$D,4,FALSE()))/2)^2)),"") -> 2135.0483 | E35: =VLOOKUP(A35,'Airport Parameters'!$A:$G,7,FALSE) -> 511500 | F35: =VLOOKUP(B35,'Airport Parameters'!$A:$G,7,FALSE) -> 414
A36: BSZ | B36: CMB | C36: 715 | D36: =IFERROR(2*3440.065*ASIN(SQRT(SIN(RADIANS(VLOOKUP($B36,'Airport Parameters'!$A:$D,3,FALSE())-VLOOKUP($A36,'Airport Parameters'!$A:$D,3,FALSE()))/2)^2+COS(RADIANS(VLOOKUP($A36,'Airport Parameters'!$A:$D,3,FALSE())))*COS(RADIANS(VLOOKUP($B36,'Airport Parameters'!$A:$D,3,FALSE())))*SIN(RADIANS(VLOOKUP($B36,'Airport Parameters'!$A:$D,4,FALSE())-VLOOKUP($A36,'Airport Parameters'!$A:$D,4,FALSE()))/2)^2)),"") -> 2173.1385 | E36: =VLOOKUP(A36,'Airport Parameters'!$A:$G,7,FALSE) -> 57939 | F36: =VLOOKUP(B36,'Airport Parameters'!$A:$G,7,FALSE) -> 956000
A37: SGN | B37: SXR | C37: 623 | D37: =IFERROR(2*3440.065*ASIN(SQRT(SIN(RADIANS(VLOOKUP($B37,'Airport Parameters'!$A:$D,3,FALSE())-VLOOKUP($A37,'Airport Parameters'!$A:$D,3,FALSE()))/2)^2+COS(RADIANS(VLOOKUP($A37,'Airport Parameters'!$A:$D,3,FALSE())))*COS(RADIANS(VLOOKUP($B37,'Airport Parameters'!$A:$D,3,FALSE())))*SIN(RADIANS(VLOOKUP($B37,'Airport Parameters'!$A:$D,4,FALSE())-VLOOKUP($A37,'Airport Parameters'!$A:$D,4,FALSE()))/2)^2)),"") -> 2233.57 | E37: =VLOOKUP(A37,'Airport Parameters'!$A:$G,7,FALSE) -> 272500 | F37: =VLOOKUP(B37,'Airport Parameters'!$A:$G,7,FALSE) -> 133750
A38: HYD | B38: UBN | C38: 577 | D38: =IFERROR(2*3440.065*ASIN(SQRT(SIN(RADIANS(VLOOKUP($B38,'Airport Parameters'!$A:$D,3,FALSE())-VLOOKUP($A38,'Airport Parameters'!$A:$D,3,FALSE()))/2)^2+COS(RADIANS(VLOOKUP($A38,'Airport Parameters'!$A:$D,3,FALSE())))*COS(RADIANS(VLOOKUP($B38,'Airport Parameters'!$A:$D,3,FALSE())))*SIN(RADIANS(VLOOKUP($B38,'Airport Parameters'!$A:$D,4,FALSE())-VLOOKUP($A38,'Airport Parameters'!$A:$D,4,FALSE()))/2)^2)),"") -> 2298.3691 | E38: =VLOOKUP(A38,'Airport Parameters'!$A:$G,7,FALSE) -> 1768000 | F38: =VLOOKUP(B38,'Airport Parameters'!$A:$G,7,FALSE) -> 104778
A39: DEL | B39: ICN | C39: 762 | D39: =IFERROR(2*3440.065*ASIN(SQRT(SIN(RADIANS(VLOOKUP($B39,'Airport Parameters'!$A:$D,3,FALSE())-VLOOKUP($A39,'Airport Parameters'!$A:$D,3,FALSE()))/2)^2+COS(RADIANS(VLOOKUP($A39,'Airport Parameters'!$A:$D,3,FALSE())))*COS(RADIANS(VLOOKUP($B39,'Airport Parameters'!$A:$D,3,FALSE())))*SIN(RADIANS(VLOOKUP($B39,'Airport Parameters'!$A:$D,4,FALSE())-VLOOKUP($A39,'Airport Parameters'!$A:$D,4,FALSE()))/2)^2)),"") -> 2512.1352 | E39: =VLOOKUP(A39,'Airport Parameters'!$A:$G,7,FALSE) -> 1787000 | F39: =VLOOKUP(B39,'Airport Parameters'!$A:$G,7,FALSE) -> 637333
A40: EDI | B40: IKA | C40: 641 | D40: =IFERROR(2*3440.065*ASIN(SQRT(SIN(RADIANS(VLOOKUP($B40,'Airport Parameters'!$A:$D,3,FALSE())-VLOOKUP($A40,'Airport Parameters'!$A:$D,3,FALSE()))/2)^2+COS(RADIANS(VLOOKUP($A40,'Airport Parameters'!$A:$D,3,FALSE())))*COS(RADIANS(VLOOKUP($B40,'Airport Parameters'!$A:$D,3,FALSE())))*SIN(RADIANS(VLOOKUP($B40,'Airport Parameters'!$A:$D,4,FALSE())-VLOOKUP($A40,'Airport Parameters'!$A:$D,4,FALSE()))/2)^2)),"") -> 2512.2793 | E40: =VLOOKUP(A40,'Airport Parameters'!$A:$G,7,FALSE) -> 296000 | F40: =VLOOKUP(B40,'Airport Parameters'!$A:$G,7,FALSE) -> 68855
A41: DLU | B41: IKA | C41: 603 | D41: =IFERROR(2*3440.065*ASIN(SQRT(SIN(RADIANS(VLOOKUP($B41,'Airport Parameters'!$A:$D,3,FALSE())-VLOOKUP($A41,'Airport Parameters'!$A:$D,3,FALSE()))/2)^2+COS(RADIANS(VLOOKUP($A41,'Airport Parameters'!$A:$D,3,FALSE())))*COS(RADIANS(VLOOKUP($B41,'Airport Parameters'!$A:$D,3,FALSE())))*SIN(RADIANS(VLOOKUP($B41,'Airport Parameters'!$A:$D,4,FALSE())-VLOOKUP($A41,'Airport Parameters'!$A:$D,4,FALSE()))/2)^2)),"") -> 2582.4571 | E41: =VLOOKUP(A41,'Airport Parameters'!$A:$G,7,FALSE) -> 26071 | F41: =VLOOKUP(B41,'Airport Parameters'!$A:$G,7,FALSE) -> 68855
... A61: ELP | B61: PBH | C61: 358 | D61: =IFERROR(2*3440.065*ASIN(SQRT(SIN(RADIANS(VLOOKUP($B61,'Airport Parameters'!$A:$D,3,FALSE())-VLOOKUP($A61,'Airport Parameters'!$A:$D,3,FALSE()))/2)^2+COS(RADIANS(VLOOKUP($A61,'Airport Parameters'!$A:$D,3,FALSE())))*COS(RADIANS(VLOOKUP($B61,'Airport Parameters'!$A:$D,3,FALSE())))*SIN(RADIANS(VLOOKUP($B61,'Airport Parameters'!$A:$D,4,FALSE())-VLOOKUP($A61,'Airport Parameters'!$A:$D,4,FALSE()))/2)^2)),"") -> 7139.1643 | E61: =VLOOKUP(A61,'Airport Parameters'!$A:$G,7,FALSE) -> 239170 | F61: =VLOOKUP(B61,'Airport Parameters'!$A:$G,7,FALSE) -> 77738
A63: Filled: | B63: =COUNTA(C2:C61)&" / 60" -> 60 / 60

Sheet Sheet1
A1: Gravity Model
A2: Raw Parameter | B2: Value | C2: GM Parameter | D2: Value
A3: Rsquare | B3: 0.74532 | C3: -
A4: Intercept Estimate | B4: 3.6308765 | C4: C | D4: =EXP(B4) -> 37.745886
A5: Log_Origin Estimate | B5: 0.1166132 | C5: α_Origin | D5: =B5 -> 0.1166132
A6: Log_Destination Estimate | B6: 0.1017242 | C6: α_Destination | D6: =B6 -> 0.1017242
A7: Prob>[t]_Intercept | B7: <0.0001 | C7: -
A8: Prob>[t]_Intercept | B8: <0.0001 | C8: -
A9: Prob>[t]_Intercept | B9: <0.0001 | C9: -
A10: Shapiro-Wilk: W = 0.943126, Prob<W = 0.0179
A12: Anderson-Darling: A^2 = 1.1452672, p-Value = 0.0048
