Workbook

Sheet Instructions
A1: H3 (Pan-Himalayan) Network Centrality Project — Data Collection Guide (v3)
A3: SHEET: Airport Parameters
A4: All 129 airports H3 holds gates at are pre-filled (IATA, name, lat, lon — real
A5: coordinates, already joined). You only need to fill in:
A6: H3 weekly pax — your own passengers per week at that destination.
A7: H3 market share % — read off that airport's competitor list in-game.
A8: Airport rank / Airport rank % — the in-game rank stat (secondary check only,
A9: used to test the Zipf/power-law hunch, NOT the primary size term).
A10: Total weekly pax fills in automatically once the two columns above are entered.
A12: SHEET: Calibration Routes
A13: 60 pairs are pre-selected for distance and size spread (using gate weekly cost as a
A14: size stand-in until real data exists) — only 1 pair touches KTM, deliberately, so
... A16: number from Route Research for each pair. Distance is already computed.

Sheet Airport Parameters
A1: IATA | B1: Airport name | C1: Lat | D1: Lon | E1: H3 weekly pax | F1: H3 market share % | G1: Total weekly pax (computed) | H1: Airport rank | I1: Airport rank % | J1: Annual Passengers (Real World) | K1: log(Rank) | L1: log(weeklyPax) | M1: log(AnnualPax) | N1: Date collected | O1: Notes | P1: Divergence
A2: MAA | B2: Chennai International Airport | C2: 12.99 | D2: 80.1693 | E2: 2048 | F2: 0.1 | G2: =ROUND(IF(F2=0,"",IF(F2="","",E2/(F2/100))),0) -> 2048000 | H2: 131 | I2: 97.08 | J2: 21207262 | K2: =LOG(H2) -> 2.1172713 | L2: =LOG(G2) -> 6.31133 | M2: =LOG(J2) -> 7.3264846 | P2: =J2*7/365 - G2 -> -1641285.4
A3: HYD | B3: Rajiv Gandhi International Airport | C3: 17.2313 | D3: 78.4299 | E3: 1768 | F3: 0.1 | G3: =ROUND(IF(F3=0,"",IF(F3="","",E3/(F3/100))),0) -> 1768000 | H3: 91 | I3: 97.97 | J3: 29166438 | K3: =LOG(H3) -> 1.9590414 | L3: =LOG(G3) -> 6.2474823 | M3: =LOG(J3) -> 7.4648834 | P3: =J3*7/365 - G3 -> -1208643.7
A4: SIN | B4: Singapore Changi Airport | C4: 1.3502 | D4: 103.994 | E4: 2448 | F4: 0.1 | G4: =ROUND(IF(F4=0,"",IF(F4="","",E4/(F4/100))),0) -> 2448000 | H4: 16 | I4: 99.64 | J4: 69980000 | K4: =LOG(H4) -> 1.20412 | L4: =LOG(G4) -> 6.3888114 | M4: =LOG(J4) -> 7.8449739 | P4: =J4*7/365 - G4 -> -1105917.8
A5: BLR | B5: Kempegowda International Airport | C5: 13.1979 | D5: 77.7063 | E5: 1768 | F5: 0.1 | G5: =ROUND(IF(F5=0,"",IF(F5="","",E5/(F5/100))),0) -> 1768000 | H5: 58 | I5: 98.71 | J5: 40730000 | K5: =LOG(H5) -> 1.763428 | L5: =LOG(G5) -> 6.2474823 | M5: =LOG(J5) -> 7.6099144 | P5: =J5*7/365 - G5 -> -986876.71
A6: PEK | B6: Beijing Capital International Airport | C6: 40.0801 | D6: 116.585 | E6: 2180 | F6: 0.1 | G6: =ROUND(IF(F6=0,"",IF(F6="","",E6/(F6/100))),0) -> 2180000 | H6: 15 | I6: 99.67 | J6: 70742712 | K6: =LOG(H6) -> 1.1760913 | L6: =LOG(G6) -> 6.3384565 | M6: =LOG(J6) -> 7.8496817 | P6: =J6*7/365 - G6 -> -823290.45
A7: CMB | B7: Bandaranaike International Airport | C7: 7.1808 | D7: 79.8841 | E7: 1912 | F7: 0.2 | G7: =ROUND(IF(F7=0,"",IF(F7="","",E7/(F7/100))),0) -> 956000 | H7: 257 | I7: 94.27 | J7: 8804019 | K7: =LOG(H7) -> 2.4099331 | L7: =LOG(G7) -> 5.9804579 | M7: =LOG(J7) -> 6.944681 | P7: =J7*7/365 - G7 -> -787155.8
A8: HKG | B8: Hong Kong International Airport | C8: 22.3089 | D8: 113.915 | E8: 1912 | F8: 0.1 | G8: =ROUND(IF(F8=0,"",IF(F8="","",E8/(F8/100))),0) -> 1912000 | H8: 24 | I8: 99.47 | J8: 60992000 | K8: =LOG(H8) -> 1.3802112 | L8: =LOG(G8) -> 6.2814879 | M8: =LOG(J8) -> 7.7852729 | P8: =J8*7/365 - G8 -> -742290.41
A9: BOM | B9: Chhatrapati Shivaji Maharaj International Airport | C9: 19.0887 | D9: 72.8679 | E9: 1768 | F9: 0.1 | G9: =ROUND(IF(F9=0,"",IF(F9="","",E9/(F9/100))),0) -> 1768000 | H9: 29 | I9: 99.35 | J9: 55500000 | K9: =LOG(H9) -> 1.462398 | L9: =LOG(G9) -> 6.2474823 | M9: =LOG(J9) -> 7.744293 | P9: =J9*7/365 - G9 -> -703616.44
A10: CCU | B10: Netaji Subhas Chandra Bose International Airport | C10: 22.6547 | D10: 88.4467 | E10: 2056 | F10: 0.2 | G10: =ROUND(IF(F10=0,"",IF(F10="","",E10/(F10/100))),0) -> 1028000 | H10: 136 | I10: 96.97 | J10: 19784417 | K10: =LOG(H10) -> 2.1335389 | L10: =LOG(G10) -> 6.0119931 | M10: =LOG(J10) -> 7.2963233 | P10: =J10*7/365 - G10 -> -648572.82
A11: TRV | B11: Thiruvananthapuram International Airport | C11: 8.4821 | D11: 76.9201 | E11: 943 | F11: 0.2 | G11: =ROUND(IF(F11=0,"",IF(F11="","",E11/(F11/100))),0) -> 471500 | H11: 388 | I11: 91.35 | J11: 4405318 | K11: =LOG(H11) -> 2.5888317 | L11: =LOG(G11) -> 5.6734817 | M11: =LOG(J11) -> 6.6439773 | P11: =J11*7/365 - G11 -> -387014.45
A12: LAX | B12: Los Angeles International Airport | C12: 33.9425 | D12: -118.408 | E12: 1742 | F12: 0.1 | G12: =ROUND(IF(F12=0,"",IF(F12="","",E12/(F12/100))),0) -> 1742000 | H12: 13 | I12: 99.71 | J12: 73709594 | K12: =LOG(H12) -> 1.1139434 | L12: =LOG(G12) -> 6.2410482 | M12: =LOG(J12) -> 7.867524 | P12: =J12*7/365 - G12 -> -328391.35
A13: IST | B13: Istanbul Airport | C13: 41.2753 | D13: 28.7519 | E13: 1912 | F13: 0.1 | G13: =ROUND(IF(F13=0,"",IF(F13="","",E13/(F13/100))),0) -> 1912000 | H13: 8 | I13: 99.82 | J13: 84457421 | K13: =LOG(H13) -> 0.90308999 | L13: =LOG(G13) -> 6.2814879 | M13: =LOG(J13) -> 7.9266378 | P13: =J13*7/365 - G13 -> -292268.64
... A16: TAS | B16: Islam Karimov Tashkent International Airport | C16: 41.2579 | D16: 69.2812 | E16: 1912 | F16: 0.5 | G16: =ROUND(IF(F16=0,"",IF(F16="","",E16/(F16/100))),0) -> 382400 | H16: 258 | I16: 94.25 | J16: 8716526 | K16: =LOG(H16) -> 2.4116197 | L16: =LOG(G16) -> 5.5825179 | M16: =LOG(J16) -> 6.9403434 | P16: =J16*7/365 - G16 -> -215233.75
A17: ELP | B17: El Paso International Airport | C17: 31.8072 | D17: -106.378 | E17: 0 | F17: 0 | G17: 239170 | H17: 432 | I17: 90.37 | J17: 3838968 | K17: =LOG(H17) -> 2.6354837 | L17: =LOG(G17) -> 5.3787067 | M17: =LOG(J17) -> 6.5842145 | P17: =J17*7/365 - G17 -> -165545.96
A18: KTM | B18: Tribhuvan International Airport | C18: 27.6966 | D18: 85.3591 | E18: 161766 | F18: 51.7 | G18: =ROUND(IF(F18=0,"",IF(F18="","",E18/(F18/100))),0) -> 312894 | H18: 252 | I18: 94.39 | J18: 8991993 | K18: =LOG(H18) -> 2.4014005 | L18: =LOG(G18) -> 5.4953972 | M18: =LOG(J18) -> 6.953856 | P18: =J18*7/365 - G18 -> -140444.82
A19: KBL | B19: Kabul International Airport | C19: 34.5659 | D19: 69.2123 | E19: 1912 | F19: 1.2 | G19: =ROUND(IF(F19=0,"",IF(F19="","",E19/(F19/100))),0) -> 159333 | H19: 845 | I19: 81.17 | J19: 1237662 | K19: =LOG(H19) -> 2.9268567 | L19: =LOG(G19) -> 5.2023057 | M19: =LOG(J19) -> 6.0926021 | P19: =J19*7/365 - G19 -> -135597.02
A20: RGN | B20: Yangon International Airport | C20: 16.9073 | D20: 96.1332 | E20: 1912 | F20: 1 | G20: =ROUND(IF(F20=0,"",IF(F20="","",E20/(F20/100))),0) -> 191200 | H20: 451 | I20: 89.95 | J20: 3622313 | K20: =LOG(H20) -> 2.6541765 | L20: =LOG(G20) -> 5.2814879 | M20: =LOG(J20) -> 6.558986 | P20: =J20*7/365 - G20 -> -121730.98
A21: BEY | B21: Beirut–Rafic Hariri International Airport | C21: 33.8209 | D21: 35.4884 | E21: 762 | F21: 0.3 | G21: =ROUND(IF(F21=0,"",IF(F21="","",E21/(F21/100))),0) -> 254000 | H21: 293 | I21: 93.47 | J21: 7127649 | K21: =LOG(H21) -> 2.4668676 | L21: =LOG(G21) -> 5.4048337 | M21: =LOG(J21) -> 6.8529463 | P21: =J21*7/365 - G21 -> -117305.36
A22: IXB | B22: Bagdogra Airport | C22: 26.6812 | D22: 88.3286 | E22: 1026 | F22: 0.6 | G22: =ROUND(IF(F22=0,"",IF(F22="","",E22/(F22/100))),0) -> 171000 | H22: 497 | I22: 88.93 | J22: 3118368 | K22: =LOG(H22) -> 2.6963564 | L22: =LOG(G22) -> 5.2329961 | M22: =LOG(J22) -> 6.4939274 | P22: =J22*7/365 - G22 -> -111195.68
A23: ESB | B23: Ankara Esenboğa Airport | C23: 40.1281 | D23: 32.9951 | E23: 1070 | F23: 0.3 | G23: =ROUND(IF(F23=0,"",IF(F23="","",E23/(F23/100))),0) -> 356667 | H23: 187 | I23: 95.83 | J23: 12853024 | K23: =LOG(H23) -> 2.2718416 | L23: =LOG(G23) -> 5.5522629 | M23: =LOG(J23) -> 7.1090053 | P23: =J23*7/365 - G23 -> -110170.65
A24: GYD | B24: Baku Heydar Aliyev International Airport | C24: 40.4675 | D24: 50.0467 | E24: 508 | F24: 0.2 | G24: =ROUND(IF(F24=0,"",IF(F24="","",E24/(F24/100))),0) -> 254000 | H24: 282 | I24: 93.72 | J24: 7537000 | K24: =LOG(H24) -> 2.4502491 | L24: =LOG(G24) -> 5.4048337 | M24: =LOG(J24) -> 6.8771985 | P24: =J24*7/365 - G24 -> -109454.79
A25: LHE | B25: Allama Iqbal International Airport | C25: 31.5216 | D25: 74.4036 | E25: 1912 | F25: 1.1 | G25: =ROUND(IF(F25=0,"",IF(F25="","",E25/(F25/100))),0) -> 173818 | H25: 442 | I25: 90.15 | J25: 3695960 | K25: =LOG(H25) -> 2.6454223 | L25: =LOG(G25) -> 5.2400947 | M25: =LOG(J25) -> 6.5677273 | P25: =J25*7/365 - G25 -> -102936.58
A26: ISB | B26: Islamabad International Airport | C26: 33.5607 | D26: 72.8516 | E26: 1070 | F26: 0.5 | G26: =ROUND(IF(F26=0,"",IF(F26="","",E26/(F26/100))),0) -> 214000 | H26: 327 | I26: 92.71 | J26: 6024221 | K26: =LOG(H26) -> 2.5145478 | L26: =LOG(G26) -> 5.3304138 | M26: =LOG(J26) -> 6.7799009 | P26: =J26*7/365 - G26 -> -98466.995
A27: KHI | B27: Jinnah International Airport | C27: 24.9065 | D27: 67.1608 | E27: 1894 | F27: 1 | G27: =ROUND(IF(F27=0,"",IF(F27="","",E27/(F27/100))),0) -> 189400 | H27: 358 | I27: 92.01 | J27: 5165904 | K27: =LOG(H27) -> 2.553883 | L27: =LOG(G27) -> 5.27738 | M27: =LOG(J27) -> 6.7131463 | P27: =J27*7/365 - G27 -> -90327.868
A28: PBH | B28: Paro International Airport | C28: 27.4032 | D28: 89.4246 | E28: 4742 | F28: 6.1 | G28: =ROUND(IF(F28=0,"",IF(F28="","",E28/(F28/100))),0) -> 77738 | H28: 1780 | I28: 60.34 | J28: 181659 | K28: =LOG(H28) -> 3.25042 | L28: =LOG(G28) -> 4.8906334 | M28: =LOG(J28) -> 5.2592569 | P28: =J28*7/365 - G28 -> -74254.129
A29: UBN | B29: Chinggis Khaan International Airport | C29: 47.6469 | D29: 106.8197 | E29: 943 | F29: 0.9 | G29: =ROUND(IF(F29=0,"",IF(F29="","",E29/(F29/100))),0) -> 104778 | H29: 618 | I29: 86.23 | J29: 2167270 | K29: =LOG(H29) -> 2.7909885 | L29: =LOG(G29) -> 5.0202701 | M29: =LOG(J29) -> 6.335913 | P29: =J29*7/365 - G29 -> -63213.918
... A38: LXA | B38: Lhasa Gonggar Airport | C38: 29.2978 | D38: 90.9119 | E38: 2524 | F38: 1.7 | G38: =ROUND(IF(F38=0,"",IF(F38="","",E38/(F38/100))),0) -> 148471 | H38: 319 | I38: 92.89 | J38: 6284823 | K38: =LOG(H38) -> 2.5037907 | L38: =LOG(G38) -> 5.1716416 | M38: =LOG(J38) -> 6.7982931 | P38: =J38*7/365 - G38 -> -27940.148
A39: BGW | B39: Baghdad International Airport | C39: 33.2625 | D39: 44.2346 | E39: 0 | F39: 0 | G39: 83789 | H39: 528 | I39: 88.24 | J39: 2915052 | K39: =LOG(H39) -> 2.7226339 | L39: =LOG(G39) -> 4.923187 | M39: =LOG(J39) -> 6.4646463 | P39: =J39*7/365 - G39 -> -27883.893
A40: KHG | B40: Kashi Laining International Airport | C40: 39.5429 | D40: 76.02 | E40: 1912 | F40: 1.5 | G40: =ROUND(IF(F40=0,"",IF(F40="","",E40/(F40/100))),0) -> 127467 | H40: 352 | I40: 92.16 | J40: 5233499 | K40: =LOG(H40) -> 2.5465427 | L40: =LOG(G40) -> 5.1053978 | M40: =LOG(J40) -> 6.7187921 | P40: =J40*7/365 - G40 -> -27098.526
A41: BBI | B41: Biju Patnaik Airport | C41: 20.2444 | D41: 85.8178 | E41: 762 | F41: 0.7 | G41: =ROUND(IF(F41=0,"",IF(F41="","",E41/(F41/100))),0) -> 108857 | H41: 384 | I41: 91.44 | J41: 4600615 | K41: =LOG(H41) -> 2.5843312 | L41: =LOG(G41) -> 5.0368564 | M41: =LOG(J41) -> 6.6628159 | P41: =J41*7/365 - G41 -> -20626.027
A42: CJB | B42: Coimbatore International Airport | C42: 11.03 | D42: 77.0434 | E42: 1528 | F42: 2.2 | G42: =ROUND(IF(F42=0,"",IF(F42="","",E42/(F42/100))),0) -> 69455 | H42: 530 | I42: 88.19 | J42: 2904611 | K42: =LOG(H42) -> 2.7242759 | L42: =LOG(G42) -> 4.8417035 | M42: =LOG(J42) -> 6.463088 | P42: =J42*7/365 - G42 -> -13750.132
A43: NMA | B43: Namangan Airport | C43: 40.9846 | D43: 71.5567 | E43: 1090 | F43: 7.1 | G43: =ROUND(IF(F43=0,"",IF(F43="","",E43/(F43/100))),0) -> 15352 | H43: 2082 | I43: 53.61 | J43: 100000 | K43: =LOG(H43) -> 3.3184807 | L43: =LOG(G43) -> 4.186165 | M43: =LOG(J43) -> 5 | P43: =J43*7/365 - G43 -> -13434.192
A44: LYR | B44: Svalbard Airport | C44: 78.2461 | D44: 15.4656 | E44: 313 | F44: 2 | G44: =ROUND(IF(F44=0,"",IF(F44="","",E44/(F44/100))),0) -> 15650 | H44: 1869 | I44: 58.36 | J44: 154261 | K44: =LOG(H44) -> 3.2716093 | L44: =LOG(G44) -> 4.1945143 | M44: =LOG(J44) -> 5.1882561 | P44: =J44*7/365 - G44 -> -12691.57
A45: PEW | B45: Bacha Khan International Airport | C45: 33.9939 | D45: 71.5146 | E45: 536 | F45: 1.3 | G45: =ROUND(IF(F45=0,"",IF(F45="","",E45/(F45/100))),0) -> 41231 | H45: 738 | I45: 83.56 | J45: 1578319 | K45: =LOG(H45) -> 2.8680564 | L45: =LOG(G45) -> 4.6152239 | M45: =LOG(J45) -> 6.1981948 | P45: =J45*7/365 - G45 -> -10961.868
A46: BHK | B46: Bukhara International Airport | C46: 39.775 | D46: 64.4833 | E46: 562 | F46: 2.7 | G46: =ROUND(IF(F46=0,"",IF(F46="","",E46/(F46/100))),0) -> 20815 | H46: 1245 | I46: 72.26 | J46: 525000 | K46: =LOG(H46) -> 3.0951694 | L46: =LOG(G46) -> 4.3183764 | M46: =LOG(J46) -> 5.7201593 | P46: =J46*7/365 - G46 -> -10746.507
A47: FNJ | B47: Pyongyang International Airport | C47: 39.2241 | D47: 125.67 | E47: 797 | F47: 8.2 | G47: =ROUND(IF(F47=0,"",IF(F47="","",E47/(F47/100))),0) -> 9720 | H47: 2441 | I47: 45.61 | J47: 46123 | K47: =LOG(H47) -> 3.3875678 | L47: =LOG(G47) -> 3.9876663 | M47: =LOG(J47) -> 4.6639175 | P47: =J47*7/365 - G47 -> -8835.4493
A48: DCY | B48: Daocheng Yading Airport | C48: 29.3231 | D48: 100.0533 | E48: 1005 | F48: 21.9 | G48: =ROUND(IF(F48=0,"",IF(F48="","",E48/(F48/100))),0) -> 4589 | H48: 2136 | I48: 52.41 | J48: 89635 | K48: =LOG(H48) -> 3.3296012 | L48: =LOG(G48) -> 3.6617181 | M48: =LOG(J48) -> 4.9524776 | P48: =J48*7/365 - G48 -> -2869.9726
A49: AMM | B49: Queen Alia International Airport | C49: 31.7226 | D49: 35.9932 | E49: 1224 | F49: 0.8 | G49: =ROUND(IF(F49=0,"",IF(F49="","",E49/(F49/100))),0) -> 153000 | H49: 275 | I49: 93.87 | J49: 7837501 | K49: =LOG(H49) -> 2.4393327 | L49: =LOG(G49) -> 5.1846914 | M49: =LOG(J49) -> 6.8941776 | P49: =J49*7/365 - G49 -> -2691.7616
A50: GZG | B50: Garze Gesar Airport | C50: 31.6492 | D50: 99.8228 | E50: 633 | F50: 21 | G50: =ROUND(IF(F50=0,"",IF(F50="","",E50/(F50/100))),0) -> 3014 | H50: 2359 | I50: 47.44 | J50: 53896 | K50: =LOG(H50) -> 3.3727279 | L50: =LOG(G50) -> 3.4791432 | M50: =LOG(J50) -> 4.7315565 | P50: =J50*7/365 - G50 -> -1980.3781
...

Sheet Calibration Routes
A1: Origin IATA | B1: Destination IATA | C1: Max Pax per Flight | D1: Distance nm (computed) | E1: Origin Size (in-game) | F1: Destination Size (in-game) | G1: Origin Size (Real-world) | H1: Destination Size (Real-world) | I1: Date collected | J1: Notes
A2: JRH | B2: SHL | C2: 210 | D2: =IFERROR(2*3440.065*ASIN(SQRT(SIN(RADIANS(VLOOKUP($B2,'Airport Parameters'!$A:$D,3,FALSE())-VLOOKUP($A2,'Airport Parameters'!$A:$D,3,FALSE()))/2)^2+COS(RADIANS(VLOOKUP($A2,'Airport Parameters'!$A:$D,3,FALSE())))*COS(RADIANS(VLOOKUP($B2,'Airport Parameters'!$A:$D,3,FALSE())))*SIN(RADIANS(VLOOKUP($B2,'Airport Parameters'!$A:$D,4,FALSE())-VLOOKUP($A2,'Airport Parameters'!$A:$D,4,FALSE()))/2)^2)),"") -> 133.45143 | E2: =VLOOKUP(A2,'Airport Parameters'!$A:$G,7,FALSE) -> 1048 | F2: =VLOOKUP(B2,'Airport Parameters'!$A:$G,7,FALSE) -> 704 | G2: =VLOOKUP(A2,'Airport Parameters'!$A:$J,10,FALSE) -> 168468 | H2: =VLOOKUP(B2,'Airport Parameters'!$A:$J,10,FALSE) -> 154658
A3: AKY | B3: MDL | C3: 119 | D3: =IFERROR(2*3440.065*ASIN(SQRT(SIN(RADIANS(VLOOKUP($B3,'Airport Parameters'!$A:$D,3,FALSE())-VLOOKUP($A3,'Airport Parameters'!$A:$D,3,FALSE()))/2)^2+COS(RADIANS(VLOOKUP($A3,'Airport Parameters'!$A:$D,3,FALSE())))*COS(RADIANS(VLOOKUP($B3,'Airport Parameters'!$A:$D,3,FALSE())))*SIN(RADIANS(VLOOKUP($B3,'Airport Parameters'!$A:$D,4,FALSE())-VLOOKUP($A3,'Airport Parameters'!$A:$D,4,FALSE()))/2)^2)),"") -> 198.00674 | E3: =VLOOKUP(A3,'Airport Parameters'!$A:$G,7,FALSE) -> 513 | F3: =VLOOKUP(B3,'Airport Parameters'!$A:$G,7,FALSE) -> 16511 | G3: =VLOOKUP(A3,'Airport Parameters'!$A:$J,10,FALSE) -> 14500 | H3: =VLOOKUP(B3,'Airport Parameters'!$A:$J,10,FALSE) -> 1400000
A4: HTN | B4: IXL | C4: 386 | D4: =IFERROR(2*3440.065*ASIN(SQRT(SIN(RADIANS(VLOOKUP($B4,'Airport Parameters'!$A:$D,3,FALSE())-VLOOKUP($A4,'Airport Parameters'!$A:$D,3,FALSE()))/2)^2+COS(RADIANS(VLOOKUP($A4,'Airport Parameters'!$A:$D,3,FALSE())))*COS(RADIANS(VLOOKUP($B4,'Airport Parameters'!$A:$D,3,FALSE())))*SIN(RADIANS(VLOOKUP($B4,'Airport Parameters'!$A:$D,4,FALSE())-VLOOKUP($A4,'Airport Parameters'!$A:$D,4,FALSE()))/2)^2)),"") -> 207.79296 | E4: =VLOOKUP(A4,'Airport Parameters'!$A:$G,7,FALSE) -> 74444 | F4: =VLOOKUP(B4,'Airport Parameters'!$A:$G,7,FALSE) -> 77857 | G4: =VLOOKUP(A4,'Airport Parameters'!$A:$J,10,FALSE) -> 1939110 | H4: =VLOOKUP(B4,'Airport Parameters'!$A:$J,10,FALSE) -> 1074426
A5: AMM | B5: NUM | C5: 168 | D5: =IFERROR(2*3440.065*ASIN(SQRT(SIN(RADIANS(VLOOKUP($B5,'Airport Parameters'!$A:$D,3,FALSE())-VLOOKUP($A5,'Airport Parameters'!$A:$D,3,FALSE()))/2)^2+COS(RADIANS(VLOOKUP($A5,'Airport Parameters'!$A:$D,3,FALSE())))*COS(RADIANS(VLOOKUP($B5,'Airport Parameters'!$A:$D,3,FALSE())))*SIN(RADIANS(VLOOKUP($B5,'Airport Parameters'!$A:$D,4,FALSE())-VLOOKUP($A5,'Airport Parameters'!$A:$D,4,FALSE()))/2)^2)),"") -> 228.68662 | E5: =VLOOKUP(A5,'Airport Parameters'!$A:$G,7,FALSE) -> 153000 | F5: =VLOOKUP(B5,'Airport Parameters'!$A:$G,7,FALSE) -> 340 | G5: =VLOOKUP(A5,'Airport Parameters'!$A:$J,10,FALSE) -> 7837501 | H5: =VLOOKUP(B5,'Airport Parameters'!$A:$J,10,FALSE) -> 25000
A6: CXB | B6: SHL | C6: 167 | D6: =IFERROR(2*3440.065*ASIN(SQRT(SIN(RADIANS(VLOOKUP($B6,'Airport Parameters'!$A:$D,3,FALSE())-VLOOKUP($A6,'Airport Parameters'!$A:$D,3,FALSE()))/2)^2+COS(RADIANS(VLOOKUP($A6,'Airport Parameters'!$A:$D,3,FALSE())))*COS(RADIANS(VLOOKUP($B6,'Airport Parameters'!$A:$D,3,FALSE())))*SIN(RADIANS(VLOOKUP($B6,'Airport Parameters'!$A:$D,4,FALSE())-VLOOKUP($A6,'Airport Parameters'!$A:$D,4,FALSE()))/2)^2)),"") -> 255.25731 | E6: =VLOOKUP(A6,'Airport Parameters'!$A:$G,7,FALSE) -> 2216 | F6: =VLOOKUP(B6,'Airport Parameters'!$A:$G,7,FALSE) -> 704 | G6: =VLOOKUP(A6,'Airport Parameters'!$A:$J,10,FALSE) -> 48719 | H6: =VLOOKUP(B6,'Airport Parameters'!$A:$J,10,FALSE) -> 154658
A7: KBL | B7: LHE | C7: 420 | D7: =IFERROR(2*3440.065*ASIN(SQRT(SIN(RADIANS(VLOOKUP($B7,'Airport Parameters'!$A:$D,3,FALSE())-VLOOKUP($A7,'Airport Parameters'!$A:$D,3,FALSE()))/2)^2+COS(RADIANS(VLOOKUP($A7,'Airport Parameters'!$A:$D,3,FALSE())))*COS(RADIANS(VLOOKUP($B7,'Airport Parameters'!$A:$D,3,FALSE())))*SIN(RADIANS(VLOOKUP($B7,'Airport Parameters'!$A:$D,4,FALSE())-VLOOKUP($A7,'Airport Parameters'!$A:$D,4,FALSE()))/2)^2)),"") -> 318.78308 | E7: =VLOOKUP(A7,'Airport Parameters'!$A:$G,7,FALSE) -> 159333 | F7: =VLOOKUP(B7,'Airport Parameters'!$A:$G,7,FALSE) -> 173818 | G7: =VLOOKUP(A7,'Airport Parameters'!$A:$J,10,FALSE) -> 1237662 | H7: =VLOOKUP(B7,'Airport Parameters'!$A:$J,10,FALSE) -> 3695960
A8: AKY | B8: MYT | C8: 105 | D8: =IFERROR(2*3440.065*ASIN(SQRT(SIN(RADIANS(VLOOKUP($B8,'Airport Parameters'!$A:$D,3,FALSE())-VLOOKUP($A8,'Airport Parameters'!$A:$D,3,FALSE()))/2)^2+COS(RADIANS(VLOOKUP($A8,'Airport Parameters'!$A:$D,3,FALSE())))*COS(RADIANS(VLOOKUP($B8,'Airport Parameters'!$A:$D,3,FALSE())))*SIN(RADIANS(VLOOKUP($B8,'Airport Parameters'!$A:$D,4,FALSE())-VLOOKUP($A8,'Airport Parameters'!$A:$D,4,FALSE()))/2)^2)),"") -> 401.03248 | E8: =VLOOKUP(A8,'Airport Parameters'!$A:$G,7,FALSE) -> 513 | F8: =VLOOKUP(B8,'Airport Parameters'!$A:$G,7,FALSE) -> 508 | G8: =VLOOKUP(A8,'Airport Parameters'!$A:$J,10,FALSE) -> 14500 | H8: =VLOOKUP(B8,'Airport Parameters'!$A:$J,10,FALSE) -> 125000
A9: LPQ | B9: SAI | C9: 419 | D9: =IFERROR(2*3440.065*ASIN(SQRT(SIN(RADIANS(VLOOKUP($B9,'Airport Parameters'!$A:$D,3,FALSE())-VLOOKUP($A9,'Airport Parameters'!$A:$D,3,FALSE()))/2)^2+COS(RADIANS(VLOOKUP($A9,'Airport Parameters'!$A:$D,3,FALSE())))*COS(RADIANS(VLOOKUP($B9,'Airport Parameters'!$A:$D,3,FALSE())))*SIN(RADIANS(VLOOKUP($B9,'Airport Parameters'!$A:$D,4,FALSE())-VLOOKUP($A9,'Airport Parameters'!$A:$D,4,FALSE()))/2)^2)),"") -> 409.09603 | E9: =VLOOKUP(A9,'Airport Parameters'!$A:$G,7,FALSE) -> 14941 | F9: =VLOOKUP(B9,'Airport Parameters'!$A:$G,7,FALSE) -> 51000 | G9: =VLOOKUP(A9,'Airport Parameters'!$A:$J,10,FALSE) -> 1000000 | H9: =VLOOKUP(B9,'Airport Parameters'!$A:$J,10,FALSE) -> 3926000
A10: DLU | B10: VTE | C10: 518 | D10: =IFERROR(2*3440.065*ASIN(SQRT(SIN(RADIANS(VLOOKUP($B10,'Airport Parameters'!$A:$D,3,FALSE())-VLOOKUP($A10,'Airport Parameters'!$A:$D,3,FALSE()))/2)^2+COS(RADIANS(VLOOKUP($A10,'Airport Parameters'!$A:$D,3,FALSE())))*COS(RADIANS(VLOOKUP($B10,'Airport Parameters'!$A:$D,3,FALSE())))*SIN(RADIANS(VLOOKUP($B10,'Airport Parameters'!$A:$D,4,FALSE())-VLOOKUP($A10,'Airport Parameters'!$A:$D,4,FALSE()))/2)^2)),"") -> 476.64229 | E10: =VLOOKUP(A10,'Airport Parameters'!$A:$G,7,FALSE) -> 26071 | F10: =VLOOKUP(B10,'Airport Parameters'!$A:$G,7,FALSE) -> 44905 | G10: =VLOOKUP(A10,'Airport Parameters'!$A:$J,10,FALSE) -> 3750473 | H10: =VLOOKUP(B10,'Airport Parameters'!$A:$J,10,FALSE) -> 2477841
A11: DCY | B11: GOQ | C11: 238 | D11: =IFERROR(2*3440.065*ASIN(SQRT(SIN(RADIANS(VLOOKUP($B11,'Airport Parameters'!$A:$D,3,FALSE())-VLOOKUP($A11,'Airport Parameters'!$A:$D,3,FALSE()))/2)^2+COS(RADIANS(VLOOKUP($A11,'Airport Parameters'!$A:$D,3,FALSE())))*COS(RADIANS(VLOOKUP($B11,'Airport Parameters'!$A:$D,3,FALSE())))*SIN(RADIANS(VLOOKUP($B11,'Airport Parameters'!$A:$D,4,FALSE())-VLOOKUP($A11,'Airport Parameters'!$A:$D,4,FALSE()))/2)^2)),"") -> 500.91779 | E11: =VLOOKUP(A11,'Airport Parameters'!$A:$G,7,FALSE) -> 4589 | F11: =VLOOKUP(B11,'Airport Parameters'!$A:$G,7,FALSE) -> 604 | G11: =VLOOKUP(A11,'Airport Parameters'!$A:$J,10,FALSE) -> 89635 | H11: =VLOOKUP(B11,'Airport Parameters'!$A:$J,10,FALSE) -> 362343
A12: MDL | B12: RKZ | C12: 286 | D12: =IFERROR(2*3440.065*ASIN(SQRT(SIN(RADIANS(VLOOKUP($B12,'Airport Parameters'!$A:$D,3,FALSE())-VLOOKUP($A12,'Airport Parameters'!$A:$D,3,FALSE()))/2)^2+COS(RADIANS(VLOOKUP($A12,'Airport Parameters'!$A:$D,3,FALSE())))*COS(RADIANS(VLOOKUP($B12,'Airport Parameters'!$A:$D,3,FALSE())))*SIN(RADIANS(VLOOKUP($B12,'Airport Parameters'!$A:$D,4,FALSE())-VLOOKUP($A12,'Airport Parameters'!$A:$D,4,FALSE()))/2)^2)),"") -> 583.99553 | E12: =VLOOKUP(A12,'Airport Parameters'!$A:$G,7,FALSE) -> 16511 | F12: =VLOOKUP(B12,'Airport Parameters'!$A:$G,7,FALSE) -> 450 | G12: =VLOOKUP(A12,'Airport Parameters'!$A:$J,10,FALSE) -> 1400000 | H12: =VLOOKUP(B12,'Airport Parameters'!$A:$J,10,FALSE) -> 125883
A13: HAN | B13: JRH | C13: 339 | D13: =IFERROR(2*3440.065*ASIN(SQRT(SIN(RADIANS(VLOOKUP($B13,'Airport Parameters'!$A:$D,3,FALSE())-VLOOKUP($A13,'Airport Parameters'!$A:$D,3,FALSE()))/2)^2+COS(RADIANS(VLOOKUP($A13,'Airport Parameters'!$A:$D,3,FALSE())))*COS(RADIANS(VLOOKUP($B13,'Airport Parameters'!$A:$D,3,FALSE())))*SIN(RADIANS(VLOOKUP($B13,'Airport Parameters'!$A:$D,4,FALSE())-VLOOKUP($A13,'Airport Parameters'!$A:$D,4,FALSE()))/2)^2)),"") -> 718.25953 | E13: =VLOOKUP(A13,'Airport Parameters'!$A:$G,7,FALSE) -> 315667 | F13: =VLOOKUP(B13,'Airport Parameters'!$A:$G,7,FALSE) -> 1048 | G13: =VLOOKUP(A13,'Airport Parameters'!$A:$J,10,FALSE) -> 29304631 | H13: =VLOOKUP(B13,'Airport Parameters'!$A:$J,10,FALSE) -> 168468
... A28: CTU | B28: KHG | C28: 623 | D28: =IFERROR(2*3440.065*ASIN(SQRT(SIN(RADIANS(VLOOKUP($B28,'Airport Parameters'!$A:$D,3,FALSE())-VLOOKUP($A28,'Airport Parameters'!$A:$D,3,FALSE()))/2)^2+COS(RADIANS(VLOOKUP($A28,'Airport Parameters'!$A:$D,3,FALSE())))*COS(RADIANS(VLOOKUP($B28,'Airport Parameters'!$A:$D,3,FALSE())))*SIN(RADIANS(VLOOKUP($B28,'Airport Parameters'!$A:$D,4,FALSE())-VLOOKUP($A28,'Airport Parameters'!$A:$D,4,FALSE()))/2)^2)),"") -> 1466.7647 | E28: =VLOOKUP(A28,'Airport Parameters'!$A:$G,7,FALSE) -> 536000 | F28: =VLOOKUP(B28,'Airport Parameters'!$A:$G,7,FALSE) -> 127467 | G28: =VLOOKUP(A28,'Airport Parameters'!$A:$J,10,FALSE) -> 33518945 | H28: =VLOOKUP(B28,'Airport Parameters'!$A:$J,10,FALSE) -> 5233499
A29: CGK | B29: MNL | C29: 401 | D29: =IFERROR(2*3440.065*ASIN(SQRT(SIN(RADIANS(VLOOKUP($B29,'Airport Parameters'!$A:$D,3,FALSE())-VLOOKUP($A29,'Airport Parameters'!$A:$D,3,FALSE()))/2)^2+COS(RADIANS(VLOOKUP($A29,'Airport Parameters'!$A:$D,3,FALSE())))*COS(RADIANS(VLOOKUP($B29,'Airport Parameters'!$A:$D,3,FALSE())))*SIN(RADIANS(VLOOKUP($B29,'Airport Parameters'!$A:$D,4,FALSE())-VLOOKUP($A29,'Airport Parameters'!$A:$D,4,FALSE()))/2)^2)),"") -> 1505.4782 | E29: =VLOOKUP(A29,'Airport Parameters'!$A:$G,7,FALSE) -> 511500 | F29: =VLOOKUP(B29,'Airport Parameters'!$A:$G,7,FALSE) -> 889000 | G29: =VLOOKUP(A29,'Airport Parameters'!$A:$J,10,FALSE) -> 56000000 | H29: =VLOOKUP(B29,'Airport Parameters'!$A:$J,10,FALSE) -> 52020000 | J29: Moderate competition for Y, Y+, low overall demanc
A30: BSZ | B30: MYT | C30: 314 | D30: =IFERROR(2*3440.065*ASIN(SQRT(SIN(RADIANS(VLOOKUP($B30,'Airport Parameters'!$A:$D,3,FALSE())-VLOOKUP($A30,'Airport Parameters'!$A:$D,3,FALSE()))/2)^2+COS(RADIANS(VLOOKUP($A30,'Airport Parameters'!$A:$D,3,FALSE())))*COS(RADIANS(VLOOKUP($B30,'Airport Parameters'!$A:$D,3,FALSE())))*SIN(RADIANS(VLOOKUP($B30,'Airport Parameters'!$A:$D,4,FALSE())-VLOOKUP($A30,'Airport Parameters'!$A:$D,4,FALSE()))/2)^2)),"") -> 1544.6785 | E30: =VLOOKUP(A30,'Airport Parameters'!$A:$G,7,FALSE) -> 57939 | F30: =VLOOKUP(B30,'Airport Parameters'!$A:$G,7,FALSE) -> 508 | G30: =VLOOKUP(A30,'Airport Parameters'!$A:$J,10,FALSE) -> 3586337 | H30: =VLOOKUP(B30,'Airport Parameters'!$A:$J,10,FALSE) -> 125000
A31: ICN | B31: LZY | C31: 509 | D31: =IFERROR(2*3440.065*ASIN(SQRT(SIN(RADIANS(VLOOKUP($B31,'Airport Parameters'!$A:$D,3,FALSE())-VLOOKUP($A31,'Airport Parameters'!$A:$D,3,FALSE()))/2)^2+COS(RADIANS(VLOOKUP($A31,'Airport Parameters'!$A:$D,3,FALSE())))*COS(RADIANS(VLOOKUP($B31,'Airport Parameters'!$A:$D,3,FALSE())))*SIN(RADIANS(VLOOKUP($B31,'Airport Parameters'!$A:$D,4,FALSE())-VLOOKUP($A31,'Airport Parameters'!$A:$D,4,FALSE()))/2)^2)),"") -> 1673.7732 | E31: =VLOOKUP(A31,'Airport Parameters'!$A:$G,7,FALSE) -> 637333 | F31: =VLOOKUP(B31,'Airport Parameters'!$A:$G,7,FALSE) -> 19429 | G31: =VLOOKUP(A31,'Airport Parameters'!$A:$J,10,FALSE) -> 74071475 | H31: =VLOOKUP(B31,'Airport Parameters'!$A:$J,10,FALSE) -> 967829
A32: DIG | B32: SKD | C32: 277 | D32: =IFERROR(2*3440.065*ASIN(SQRT(SIN(RADIANS(VLOOKUP($B32,'Airport Parameters'!$A:$D,3,FALSE())-VLOOKUP($A32,'Airport Parameters'!$A:$D,3,FALSE()))/2)^2+COS(RADIANS(VLOOKUP($A32,'Airport Parameters'!$A:$D,3,FALSE())))*COS(RADIANS(VLOOKUP($B32,'Airport Parameters'!$A:$D,3,FALSE())))*SIN(RADIANS(VLOOKUP($B32,'Airport Parameters'!$A:$D,4,FALSE())-VLOOKUP($A32,'Airport Parameters'!$A:$D,4,FALSE()))/2)^2)),"") -> 1769.1102 | E32: =VLOOKUP(A32,'Airport Parameters'!$A:$G,7,FALSE) -> 6718 | F32: =VLOOKUP(B32,'Airport Parameters'!$A:$G,7,FALSE) -> 18169 | G32: =VLOOKUP(A32,'Airport Parameters'!$A:$J,10,FALSE) -> 428318 | H32: =VLOOKUP(B32,'Airport Parameters'!$A:$J,10,FALSE) -> 1380000
A33: ALA | B33: RUH | C33: 657 | D33: =IFERROR(2*3440.065*ASIN(SQRT(SIN(RADIANS(VLOOKUP($B33,'Airport Parameters'!$A:$D,3,FALSE())-VLOOKUP($A33,'Airport Parameters'!$A:$D,3,FALSE()))/2)^2+COS(RADIANS(VLOOKUP($A33,'Airport Parameters'!$A:$D,3,FALSE())))*COS(RADIANS(VLOOKUP($B33,'Airport Parameters'!$A:$D,3,FALSE())))*SIN(RADIANS(VLOOKUP($B33,'Airport Parameters'!$A:$D,4,FALSE())-VLOOKUP($A33,'Airport Parameters'!$A:$D,4,FALSE()))/2)^2)),"") -> 1851.6097 | E33: =VLOOKUP(A33,'Airport Parameters'!$A:$G,7,FALSE) -> 159333 | F33: =VLOOKUP(B33,'Airport Parameters'!$A:$G,7,FALSE) -> 356667 | G33: =VLOOKUP(A33,'Airport Parameters'!$A:$J,10,FALSE) -> 11426650 | H33: =VLOOKUP(B33,'Airport Parameters'!$A:$J,10,FALSE) -> 26500000
A34: GZG | B34: TRV | C34: 262 | D34: =IFERROR(2*3440.065*ASIN(SQRT(SIN(RADIANS(VLOOKUP($B34,'Airport Parameters'!$A:$D,3,FALSE())-VLOOKUP($A34,'Airport Parameters'!$A:$D,3,FALSE()))/2)^2+COS(RADIANS(VLOOKUP($A34,'Airport Parameters'!$A:$D,3,FALSE())))*COS(RADIANS(VLOOKUP($B34,'Airport Parameters'!$A:$D,3,FALSE())))*SIN(RADIANS(VLOOKUP($B34,'Airport Parameters'!$A:$D,4,FALSE())-VLOOKUP($A34,'Airport Parameters'!$A:$D,4,FALSE()))/2)^2)),"") -> 1888.9911 | E34: =VLOOKUP(A34,'Airport Parameters'!$A:$G,7,FALSE) -> 3014 | F34: =VLOOKUP(B34,'Airport Parameters'!$A:$G,7,FALSE) -> 471500 | G34: =VLOOKUP(A34,'Airport Parameters'!$A:$J,10,FALSE) -> 53896 | H34: =VLOOKUP(B34,'Airport Parameters'!$A:$J,10,FALSE) -> 4405318
A35: CGK | B35: IXI | C35: 250 | D35: =IFERROR(2*3440.065*ASIN(SQRT(SIN(RADIANS(VLOOKUP($B35,'Airport Parameters'!$A:$D,3,FALSE())-VLOOKUP($A35,'Airport Parameters'!$A:$D,3,FALSE()))/2)^2+COS(RADIANS(VLOOKUP($A35,'Airport Parameters'!$A:$D,3,FALSE())))*COS(RADIANS(VLOOKUP($B35,'Airport Parameters'!$A:$D,3,FALSE())))*SIN(RADIANS(VLOOKUP($B35,'Airport Parameters'!$A:$D,4,FALSE())-VLOOKUP($A35,'Airport Parameters'!$A:$D,4,FALSE()))/2)^2)),"") -> 2135.0483 | E35: =VLOOKUP(A35,'Airport Parameters'!$A:$G,7,FALSE) -> 511500 | F35: =VLOOKUP(B35,'Airport Parameters'!$A:$G,7,FALSE) -> 414 | G35: =VLOOKUP(A35,'Airport Parameters'!$A:$J,10,FALSE) -> 56000000 | H35: =VLOOKUP(B35,'Airport Parameters'!$A:$J,10,FALSE) -> 36172
A36: BSZ | B36: CMB | C36: 715 | D36: =IFERROR(2*3440.065*ASIN(SQRT(SIN(RADIANS(VLOOKUP($B36,'Airport Parameters'!$A:$D,3,FALSE())-VLOOKUP($A36,'Airport Parameters'!$A:$D,3,FALSE()))/2)^2+COS(RADIANS(VLOOKUP($A36,'Airport Parameters'!$A:$D,3,FALSE())))*COS(RADIANS(VLOOKUP($B36,'Airport Parameters'!$A:$D,3,FALSE())))*SIN(RADIANS(VLOOKUP($B36,'Airport Parameters'!$A:$D,4,FALSE())-VLOOKUP($A36,'Airport Parameters'!$A:$D,4,FALSE()))/2)^2)),"") -> 2173.1385 | E36: =VLOOKUP(A36,'Airport Parameters'!$A:$G,7,FALSE) -> 57939 | F36: =VLOOKUP(B36,'Airport Parameters'!$A:$G,7,FALSE) -> 956000 | G36: =VLOOKUP(A36,'Airport Parameters'!$A:$J,10,FALSE) -> 3586337 | H36: =VLOOKUP(B36,'Airport Parameters'!$A:$J,10,FALSE) -> 8804019
A37: SGN | B37: SXR | C37: 623 | D37: =IFERROR(2*3440.065*ASIN(SQRT(SIN(RADIANS(VLOOKUP($B37,'Airport Parameters'!$A:$D,3,FALSE())-VLOOKUP($A37,'Airport Parameters'!$A:$D,3,FALSE()))/2)^2+COS(RADIANS(VLOOKUP($A37,'Airport Parameters'!$A:$D,3,FALSE())))*COS(RADIANS(VLOOKUP($B37,'Airport Parameters'!$A:$D,3,FALSE())))*SIN(RADIANS(VLOOKUP($B37,'Airport Parameters'!$A:$D,4,FALSE())-VLOOKUP($A37,'Airport Parameters'!$A:$D,4,FALSE()))/2)^2)),"") -> 2233.57 | E37: =VLOOKUP(A37,'Airport Parameters'!$A:$G,7,FALSE) -> 272500 | F37: =VLOOKUP(B37,'Airport Parameters'!$A:$G,7,FALSE) -> 133750 | G37: =VLOOKUP(A37,'Airport Parameters'!$A:$J,10,FALSE) -> 39859384 | H37: =VLOOKUP(B37,'Airport Parameters'!$A:$J,10,FALSE) -> 4205541
A38: HYD | B38: UBN | C38: 577 | D38: =IFERROR(2*3440.065*ASIN(SQRT(SIN(RADIANS(VLOOKUP($B38,'Airport Parameters'!$A:$D,3,FALSE())-VLOOKUP($A38,'Airport Parameters'!$A:$D,3,FALSE()))/2)^2+COS(RADIANS(VLOOKUP($A38,'Airport Parameters'!$A:$D,3,FALSE())))*COS(RADIANS(VLOOKUP($B38,'Airport Parameters'!$A:$D,3,FALSE())))*SIN(RADIANS(VLOOKUP($B38,'Airport Parameters'!$A:$D,4,FALSE())-VLOOKUP($A38,'Airport Parameters'!$A:$D,4,FALSE()))/2)^2)),"") -> 2298.3691 | E38: =VLOOKUP(A38,'Airport Parameters'!$A:$G,7,FALSE) -> 1768000 | F38: =VLOOKUP(B38,'Airport Parameters'!$A:$G,7,FALSE) -> 104778 | G38: =VLOOKUP(A38,'Airport Parameters'!$A:$J,10,FALSE) -> 29166438 | H38: =VLOOKUP(B38,'Airport Parameters'!$A:$J,10,FALSE) -> 2167270
A39: DEL | B39: ICN | C39: 762 | D39: =IFERROR(2*3440.065*ASIN(SQRT(SIN(RADIANS(VLOOKUP($B39,'Airport Parameters'!$A:$D,3,FALSE())-VLOOKUP($A39,'Airport Parameters'!$A:$D,3,FALSE()))/2)^2+COS(RADIANS(VLOOKUP($A39,'Airport Parameters'!$A:$D,3,FALSE())))*COS(RADIANS(VLOOKUP($B39,'Airport Parameters'!$A:$D,3,FALSE())))*SIN(RADIANS(VLOOKUP($B39,'Airport Parameters'!$A:$D,4,FALSE())-VLOOKUP($A39,'Airport Parameters'!$A:$D,4,FALSE()))/2)^2)),"") -> 2512.1352 | E39: =VLOOKUP(A39,'Airport Parameters'!$A:$G,7,FALSE) -> 1787000 | F39: =VLOOKUP(B39,'Airport Parameters'!$A:$G,7,FALSE) -> 637333 | G39: =VLOOKUP(A39,'Airport Parameters'!$A:$J,10,FALSE) -> 79259890 | H39: =VLOOKUP(B39,'Airport Parameters'!$A:$J,10,FALSE) -> 74071475
A40: EDI | B40: IKA | C40: 641 | D40: =IFERROR(2*3440.065*ASIN(SQRT(SIN(RADIANS(VLOOKUP($B40,'Airport Parameters'!$A:$D,3,FALSE())-VLOOKUP($A40,'Airport Parameters'!$A:$D,3,FALSE()))/2)^2+COS(RADIANS(VLOOKUP($A40,'Airport Parameters'!$A:$D,3,FALSE())))*COS(RADIANS(VLOOKUP($B40,'Airport Parameters'!$A:$D,3,FALSE())))*SIN(RADIANS(VLOOKUP($B40,'Airport Parameters'!$A:$D,4,FALSE())-VLOOKUP($A40,'Airport Parameters'!$A:$D,4,FALSE()))/2)^2)),"") -> 2512.2793 | E40: =VLOOKUP(A40,'Airport Parameters'!$A:$G,7,FALSE) -> 296000 | F40: =VLOOKUP(B40,'Airport Parameters'!$A:$G,7,FALSE) -> 68855 | G40: =VLOOKUP(A40,'Airport Parameters'!$A:$J,10,FALSE) -> 15837102 | H40: =VLOOKUP(B40,'Airport Parameters'!$A:$J,10,FALSE) -> 7271338
A41: DLU | B41: IKA | C41: 603 | D41: =IFERROR(2*3440.065*ASIN(SQRT(SIN(RADIANS(VLOOKUP($B41,'Airport Parameters'!$A:$D,3,FALSE())-VLOOKUP($A41,'Airport Parameters'!$A:$D,3,FALSE()))/2)^2+COS(RADIANS(VLOOKUP($A41,'Airport Parameters'!$A:$D,3,FALSE())))*COS(RADIANS(VLOOKUP($B41,'Airport Parameters'!$A:$D,3,FALSE())))*SIN(RADIANS(VLOOKUP($B41,'Airport Parameters'!$A:$D,4,FALSE())-VLOOKUP($A41,'Airport Parameters'!$A:$D,4,FALSE()))/2)^2)),"") -> 2582.4571 | E41: =VLOOKUP(A41,'Airport Parameters'!$A:$G,7,FALSE) -> 26071 | F41: =VLOOKUP(B41,'Airport Parameters'!$A:$G,7,FALSE) -> 68855 | G41: =VLOOKUP(A41,'Airport Parameters'!$A:$J,10,FALSE) -> 3750473 | H41: =VLOOKUP(B41,'Airport Parameters'!$A:$J,10,FALSE) -> 7271338
... A61: ELP | B61: PBH | C61: 358 | D61: =IFERROR(2*3440.065*ASIN(SQRT(SIN(RADIANS(VLOOKUP($B61,'Airport Parameters'!$A:$D,3,FALSE())-VLOOKUP($A61,'Airport Parameters'!$A:$D,3,FALSE()))/2)^2+COS(RADIANS(VLOOKUP($A61,'Airport Parameters'!$A:$D,3,FALSE())))*COS(RADIANS(VLOOKUP($B61,'Airport Parameters'!$A:$D,3,FALSE())))*SIN(RADIANS(VLOOKUP($B61,'Airport Parameters'!$A:$D,4,FALSE())-VLOOKUP($A61,'Airport Parameters'!$A:$D,4,FALSE()))/2)^2)),"") -> 7139.1643 | E61: =VLOOKUP(A61,'Airport Parameters'!$A:$G,7,FALSE) -> 239170 | F61: =VLOOKUP(B61,'Airport Parameters'!$A:$G,7,FALSE) -> 77738 | G61: =VLOOKUP(A61,'Airport Parameters'!$A:$J,10,FALSE) -> 3838968 | H61: =VLOOKUP(B61,'Airport Parameters'!$A:$J,10,FALSE) -> 181659
A63: Filled: | B63: =COUNTA(C2:C61)&" / 60" -> 60 / 60

Sheet JMP Results
A1: In-Game Full Analysis | F1: In-Game Partial Analysis | L1: In-Game Partial, Actual vs. Predicted | X1: k | Y1: Spearman_rho | Z1: KTM | AA1: GAU | AB1: CCU | AC1: DEL | AD1: LXA | AE1: DAC
A2: Parameter | B2: Value | C2: Model Param. | D2: Value | F2: Parameter | G2: Value | H2: Model Param. | I2: Value | X2: 0 | Y2: 1 | Z2: 35 | AA2: 53 | AB2: 15 | AC2: 6 | AD2: 58 | AE2: 47
A3: RSquare | B3: 0.75091 | C3: - | D3: - | F3: RSquare | G3: 0.74532 | H3: - | I3: - | X3: 0.2 | Y3: 0.9125 | Z3: 14 | AA3: 21 | AB3: 4 | AC3: 1 | AD3: 29 | AE3: 17
A4: RMSE | B4: 0.256936 | C4: - | D4: - | F4: RMSE | G4: 0.257514 | H4: - | I4: - | X4: 0.4 | Y4: 0.6936 | Z4: 9 | AA4: 8 | AB4: 2 | AC4: 1 | AD4: 14 | AE4: 7
A5: Intercept Estimate | B5: 3.4209934 | C5: C | D5: =EXP(B5) -> 30.599798 | F5: Intercept Estimate | G5: 3.6308765 | H5: C | I5: =EXP(G5) -> 37.745886 | X5: 0.6 | Y5: 0.4535 | Z5: 5 | AA5: 3 | AB5: 1 | AC5: 2 | AD5: 10 | AE5: 4
A6: Intercept Prob>|t| | B6: <0.0001 | C6: - | D6: - | F6: Intercept Prob>|t| | G6: <0.0001 | H6: - | I6: - | X6: 0.8 | Y6: 0.1857 | Z6: 6 | AA6: 1 | AB6: 2 | AC6: 4 | AD6: 7 | AE6: 3
A7: Log_Distance Estimate | B7: 0.0459076 | C7: k | D7: =-B7 -> -0.0459076 | F7: Log_Osize_game Estimate | G7: 0.1166132 | H7: α_o | I7: =G7 -> 0.1166132 | X7: 1 | Y7: -0.0419 | Z7: 9 | AA7: 1 | AB7: 3 | AC7: 8 | AD7: 7 | AE7: 2
A8: Log_Distance Prob>|t| | B8: 0.2671 | C8: - | D8: - | F8: Log_Osize_game Prob>|t| | G8: <0.0001 | H8: - | I8: - | X8: 1.2 | Y8: -0.182 | Z8: 11 | AA8: 1 | AB8: 3 | AC8: 17 | AD8: 8 | AE8: 2
A9: Log_Osize_game Estimate | B9: 0.111809 | C9: α_o | D9: =B9 -> 0.111809 | F9: Log_Dsize_game Estimate | G9: 0.1017242 | H9: α_d | I9: =G9 -> 0.1017242 | X9: 1.4 | Y9: -0.2689 | Z9: 19 | AA9: 1 | AB9: 12 | AC9: 23 | AD9: 16 | AE9: 2
A10: Log_Osize_game Prob>|t| | B10: <0.0001 | C10: - | D10: - | F10: Log_Dsize_game Prob>|t| | G10: <0.0001 | H10: - | I10: -
A11: Log_Dsize_game Estimate | B11: 0.0947995 | C11: α_d | D11: =B11 -> 0.0947995
A12: Log_Dsize_game Prob>|t| | B12: <0.0001 | C12: - | D12: -
A14: Real World Full Analysis | F14: Real World Partial Analysis | L14: Real-World Partial, Actual vs. Predicted
A15: Parameter | B15: Value | C15: Model Param. | D15: Value | F15: Parameter | G15: Value | H15: Model Param. | I15: Value
A16: RSquare | B16: 0.817333 | C16: - | D16: - | F16: RSquare | G16: 0.816254 | H16: - | I16: -
A17: RMSE | B17: 0.220028 | C17: - | D17: - | F17: RMSE | G17: 0.218732 | H17: - | I17: -
A18: Intercept Estimate | B18: 2.2484518 | C18: C | D18: =EXP(B18) -> 9.4730583 | F18: Intercept Estimate | G18: 2.3093022 | H18: C | I18: =EXP(G18) -> 10.067397
A19: Intercept Prob>|t| | B19: <0.0001 | C19: - | D19: - | F19: Intercept Prob>|t| | G19: <0.0001 | H19: - | I19: -
A20: Log_Distance Estimate | B20: 0.0203882 | C20: k | D20: =-B20 -> -0.0203882 | F20: Log_Osize_real Estimate | G20: 0.123911 | H20: α_o | I20: =G20 -> 0.123911
A21: Log_Distance Prob>|t| | B21: 0.5676 | C21: - | D21: - | F21: Log_Osize_real Prob>|t| | G21: <0.0001 | H21: - | I21: -
A22: Log_Osize_real Estimate | B22: 0.1215241 | C22: α_o | D22: =B22 -> 0.1215241 | F22: Log_Dsize_real Estimate | G22: 0.1245906 | H22: α_d | I22: =G22 -> 0.1245906
A23: Log_Osize_real Prob>|t| | B23: <0.0001 | C23: - | D23: - | F23: Log_Dsize_real Prob>|t| | G23: <0.0001 | H23: - | I23: -
A24: Log_Dsize_real Estimate | B24: 0.1209985 | C24: α_d | D24: =B24 -> 0.1209985
A25: Log_Dsize_real Prob>|t| | B25: <0.0001 | C25: - | D25: -
L29: Zipf Check
